Workbook

Sheet Mapping Bu Gita
A1: Branch | B1: Divisi | C1: Kode Sales | D1: Februari | E1: Masuk | F1: Keluar | G1: NIK | H1: No Rek | I1: Data HR | J1: Status | K1: Sales Pengganti
A2: =IF(LEFT(RIGHT(C2,2),1)="0","Bandung",IF(LEFT(RIGHT(C2,2),1)="2","PCK",IF(LEFT(RIGHT(C2,2),1)="6","Cirebon",IF(LEFT(RIGHT(C2,2),1)="7","Tasik",IF(LEFT(RIGHT(C2,2),1)="8","Bogor",""))))) -> Bandung | B2: =IF(LEFT(C2,2)="EL","Elektrik",IF(LEFT(C2,2)="PP","Pipa Pompa",IF(LEFT(C2,2)="IC","ICI",IF(LEFT(C2,2)="PI","Pipamas","")))) -> Elektrik | C2: ELMOD01 | D2: RIDWAN FAUZAN FIRDAUS | E2: 44588 | G2: =VLOOKUP(Table7910111213[[#This Row],[Februari]],'Clean Data HR'!$G$2:$H$102,2,0) -> PMD2201011 | H2: 4371314568 | I2: RIDWAN FAUZAN FIRDAUS | J2: =Table7910111213[[#This Row],[Februari]]=Table7910111213[[#This Row],[Data HR]] -> TRUE | M2: Resign
A3: =IF(LEFT(RIGHT(C3,2),1)="0","Bandung",IF(LEFT(RIGHT(C3,2),1)="2","PCK",IF(LEFT(RIGHT(C3,2),1)="6","Cirebon",IF(LEFT(RIGHT(C3,2),1)="7","Tasik",IF(LEFT(RIGHT(C3,2),1)="8","Bogor",""))))) -> Bandung | B3: =IF(LEFT(C3,2)="EL","Elektrik",IF(LEFT(C3,2)="PP","Pipa Pompa",IF(LEFT(C3,2)="IC","ICI",IF(LEFT(C3,2)="PI","Pipamas","")))) -> Elektrik | C3: ELMOD02 | D3: OKKY MAULANA EKWANUR | E3: 46058 | G3: PMD2602004 | H3: 0084433621 | I3: Sales tidak ada di data HR | J3: =Table7910111213[[#This Row],[Februari]]=Table7910111213[[#This Row],[Data HR]] -> FALSE | M3: NIK | N3: Nama
A4: =IF(LEFT(RIGHT(C4,2),1)="0","Bandung",IF(LEFT(RIGHT(C4,2),1)="2","PCK",IF(LEFT(RIGHT(C4,2),1)="6","Cirebon",IF(LEFT(RIGHT(C4,2),1)="7","Tasik",IF(LEFT(RIGHT(C4,2),1)="8","Bogor",""))))) -> Bandung | B4: =IF(LEFT(C4,2)="EL","Elektrik",IF(LEFT(C4,2)="PP","Pipa Pompa",IF(LEFT(C4,2)="IC","ICI",IF(LEFT(C4,2)="PI","Pipamas","")))) -> Elektrik | C4: ELSLE01 | D4: RENALDI AGUSTIANA YUSUF | E4: 46006 | G4: =VLOOKUP(Table7910111213[[#This Row],[Februari]],'Clean Data HR'!$G$2:$H$102,2,0) -> PMD2512008 | H4: 3741721129 | I4: RENALDI AGUSTIANA YUSUF | J4: =Table7910111213[[#This Row],[Februari]]=Table7910111213[[#This Row],[Data HR]] -> TRUE | M4: PMD2201006 | N4: DADAN HARDIANSAH PUTRA
A5: =IF(LEFT(RIGHT(C5,2),1)="0","Bandung",IF(LEFT(RIGHT(C5,2),1)="2","PCK",IF(LEFT(RIGHT(C5,2),1)="6","Cirebon",IF(LEFT(RIGHT(C5,2),1)="7","Tasik",IF(LEFT(RIGHT(C5,2),1)="8","Bogor",""))))) -> Bandung | B5: =IF(LEFT(C5,2)="EL","Elektrik",IF(LEFT(C5,2)="PP","Pipa Pompa",IF(LEFT(C5,2)="IC","ICI",IF(LEFT(C5,2)="PI","Pipamas","")))) -> Elektrik | C5: ELSLE02 | D5: SYAMSUL PALAH | E5: 45533 | G5: =VLOOKUP(Table7910111213[[#This Row],[Februari]],'Clean Data HR'!$G$2:$H$102,2,0) -> PMD2408006 | H5: 7940315390 | I5: SYAMSUL PALAH | J5: =Table7910111213[[#This Row],[Februari]]=Table7910111213[[#This Row],[Data HR]] -> TRUE | M5: PMB2411001 | N5: ANTONIO RIFALDO
A6: =IF(LEFT(RIGHT(C6,2),1)="0","Bandung",IF(LEFT(RIGHT(C6,2),1)="2","PCK",IF(LEFT(RIGHT(C6,2),1)="6","Cirebon",IF(LEFT(RIGHT(C6,2),1)="7","Tasik",IF(LEFT(RIGHT(C6,2),1)="8","Bogor",""))))) -> Bandung | B6: =IF(LEFT(C6,2)="EL","Elektrik",IF(LEFT(C6,2)="PP","Pipa Pompa",IF(LEFT(C6,2)="IC","ICI",IF(LEFT(C6,2)="PI","Pipamas","")))) -> Elektrik | C6: ELSLE03 | D6: GHISAN AL AZHALI | E6: 45628 | G6: =VLOOKUP(Table7910111213[[#This Row],[Februari]],'Clean Data HR'!$G$2:$H$102,2,0) -> PMD2412001 | H6: 7495077144 | I6: GHISAN AL AZHALI | J6: =Table7910111213[[#This Row],[Februari]]=Table7910111213[[#This Row],[Data HR]] -> TRUE | M6: PMT2010001 | N6: RUDI RUSWANDI
A7: =IF(LEFT(RIGHT(C7,2),1)="0","Bandung",IF(LEFT(RIGHT(C7,2),1)="2","PCK",IF(LEFT(RIGHT(C7,2),1)="6","Cirebon",IF(LEFT(RIGHT(C7,2),1)="7","Tasik",IF(LEFT(RIGHT(C7,2),1)="8","Bogor",""))))) -> Bandung | B7: =IF(LEFT(C7,2)="EL","Elektrik",IF(LEFT(C7,2)="PP","Pipa Pompa",IF(LEFT(C7,2)="IC","ICI",IF(LEFT(C7,2)="PI","Pipamas","")))) -> Elektrik | C7: ELSLE04 | D7: VIRSQI INDRA PERDANA | E7: 46000 | G7: =VLOOKUP(Table7910111213[[#This Row],[Februari]],'Clean Data HR'!$G$2:$H$102,2,0) -> PMD2512005 | H7: 1390637132 | I7: VIRSQI INDRA PERDANA | J7: =Table7910111213[[#This Row],[Februari]]=Table7910111213[[#This Row],[Data HR]] -> TRUE | M7: PMD2601002 | N7: FITRAH RAMADHAN
A8: =IF(LEFT(RIGHT(C8,2),1)="0","Bandung",IF(LEFT(RIGHT(C8,2),1)="2","PCK",IF(LEFT(RIGHT(C8,2),1)="6","Cirebon",IF(LEFT(RIGHT(C8,2),1)="7","Tasik",IF(LEFT(RIGHT(C8,2),1)="8","Bogor",""))))) -> Bandung | B8: =IF(LEFT(C8,2)="EL","Elektrik",IF(LEFT(C8,2)="PP","Pipa Pompa",IF(LEFT(C8,2)="IC","ICI",IF(LEFT(C8,2)="PI","Pipamas","")))) -> Elektrik | C8: ELSLE05 | D8: HASUDUNGAN | E8: 44704 | G8: =VLOOKUP(Table7910111213[[#This Row],[Februari]],'Clean Data HR'!$G$2:$H$102,2,0) -> PMD2205003 | H8: 2810384045 | I8: HASUDUNGAN | J8: =Table7910111213[[#This Row],[Februari]]=Table7910111213[[#This Row],[Data HR]] -> TRUE
A9: =IF(LEFT(RIGHT(C9,2),1)="0","Bandung",IF(LEFT(RIGHT(C9,2),1)="2","PCK",IF(LEFT(RIGHT(C9,2),1)="6","Cirebon",IF(LEFT(RIGHT(C9,2),1)="7","Tasik",IF(LEFT(RIGHT(C9,2),1)="8","Bogor",""))))) -> Bandung | B9: =IF(LEFT(C9,2)="EL","Elektrik",IF(LEFT(C9,2)="PP","Pipa Pompa",IF(LEFT(C9,2)="IC","ICI",IF(LEFT(C9,2)="PI","Pipamas","")))) -> Elektrik | C9: ELCOS01 | D9: NUR ALI | E9: 44706 | G9: =VLOOKUP(Table7910111213[[#This Row],[Februari]],'Clean Data HR'!$G$2:$H$102,2,0) -> PMD2205006 | H9: 8100893330 | I9: NUR ALI | J9: =Table7910111213[[#This Row],[Februari]]=Table7910111213[[#This Row],[Data HR]] -> TRUE
A10: =IF(LEFT(RIGHT(C10,2),1)="0","Bandung",IF(LEFT(RIGHT(C10,2),1)="2","PCK",IF(LEFT(RIGHT(C10,2),1)="6","Cirebon",IF(LEFT(RIGHT(C10,2),1)="7","Tasik",IF(LEFT(RIGHT(C10,2),1)="8","Bogor",""))))) -> PCK | B10: =IF(LEFT(C10,2)="EL","Elektrik",IF(LEFT(C10,2)="PP","Pipa Pompa",IF(LEFT(C10,2)="IC","ICI",IF(LEFT(C10,2)="PI","Pipamas","")))) -> Elektrik | C10: ELSLE25 | D10: KIKI HADISURYA | E10: 45649 | G10: =VLOOKUP(Table7910111213[[#This Row],[Februari]],'Clean Data HR'!$G$2:$H$102,2,0) -> PMK2412001 | H10: 0087042531 | I10: KIKI HADISURYA | J10: =Table7910111213[[#This Row],[Februari]]=Table7910111213[[#This Row],[Data HR]] -> TRUE
A11: =IF(LEFT(RIGHT(C11,2),1)="0","Bandung",IF(LEFT(RIGHT(C11,2),1)="2","PCK",IF(LEFT(RIGHT(C11,2),1)="6","Cirebon",IF(LEFT(RIGHT(C11,2),1)="7","Tasik",IF(LEFT(RIGHT(C11,2),1)="8","Bogor",""))))) -> Cirebon | B11: =IF(LEFT(C11,2)="EL","Elektrik",IF(LEFT(C11,2)="PP","Pipa Pompa",IF(LEFT(C11,2)="IC","ICI",IF(LEFT(C11,2)="PI","Pipamas","")))) -> Elektrik | C11: ELSLE60 | D11: NURFADILAH | E11: 44951 | G11: =VLOOKUP(Table7910111213[[#This Row],[Februari]],'Clean Data HR'!$G$2:$H$102,2,0) -> PMC2301001 | H11: 1342293292 | I11: NURFADILAH | J11: =Table7910111213[[#This Row],[Februari]]=Table7910111213[[#This Row],[Data HR]] -> TRUE
A12: =IF(LEFT(RIGHT(C12,2),1)="0","Bandung",IF(LEFT(RIGHT(C12,2),1)="2","PCK",IF(LEFT(RIGHT(C12,2),1)="6","Cirebon",IF(LEFT(RIGHT(C12,2),1)="7","Tasik",IF(LEFT(RIGHT(C12,2),1)="8","Bogor",""))))) -> Cirebon | B12: =IF(LEFT(C12,2)="EL","Elektrik",IF(LEFT(C12,2)="PP","Pipa Pompa",IF(LEFT(C12,2)="IC","ICI",IF(LEFT(C12,2)="PI","Pipamas","")))) -> Elektrik | C12: ELSLE61 | D12: FANJI BERLIANDY AZHARI RIDZKI | E12: 44536 | G12: =VLOOKUP(Table7910111213[[#This Row],[Februari]],'Clean Data HR'!$G$2:$H$102,2,0) -> PMC2112006 | H12: 8180224085 | I12: FANJI BERLIANDY AZHARI RIDZKI | J12: =Table7910111213[[#This Row],[Februari]]=Table7910111213[[#This Row],[Data HR]] -> TRUE
A13: =IF(LEFT(RIGHT(C13,2),1)="0","Bandung",IF(LEFT(RIGHT(C13,2),1)="2","PCK",IF(LEFT(RIGHT(C13,2),1)="6","Cirebon",IF(LEFT(RIGHT(C13,2),1)="7","Tasik",IF(LEFT(RIGHT(C13,2),1)="8","Bogor",""))))) -> Cirebon | B13: =IF(LEFT(C13,2)="EL","Elektrik",IF(LEFT(C13,2)="PP","Pipa Pompa",IF(LEFT(C13,2)="IC","ICI",IF(LEFT(C13,2)="PI","Pipamas","")))) -> Elektrik | C13: ELSLE62 | D13: ADE TRIHANDOYO | E13: 45845 | G13: PMC2507002 | H13: 373802651 | I13: ADE TRIHANDOYO | J13: =Table7910111213[[#This Row],[Februari]]=Table7910111213[[#This Row],[Data HR]] -> TRUE
A14: =IF(LEFT(RIGHT(C14,2),1)="0","Bandung",IF(LEFT(RIGHT(C14,2),1)="2","PCK",IF(LEFT(RIGHT(C14,2),1)="6","Cirebon",IF(LEFT(RIGHT(C14,2),1)="7","Tasik",IF(LEFT(RIGHT(C14,2),1)="8","Bogor",""))))) -> Cirebon | B14: =IF(LEFT(C14,2)="EL","Elektrik",IF(LEFT(C14,2)="PP","Pipa Pompa",IF(LEFT(C14,2)="IC","ICI",IF(LEFT(C14,2)="PI","Pipamas","")))) -> Elektrik | C14: ELSLE63 | D14: FIDYAH FAROID | E14: 45502 | G14: =VLOOKUP(Table7910111213[[#This Row],[Februari]],'Clean Data HR'!$G$2:$H$102,2,0) -> PMC2407004 | H14: 8180505475 | I14: FIDYAH FAROID | J14: =Table7910111213[[#This Row],[Februari]]=Table7910111213[[#This Row],[Data HR]] -> TRUE
A15: =IF(LEFT(RIGHT(C15,2),1)="0","Bandung",IF(LEFT(RIGHT(C15,2),1)="2","PCK",IF(LEFT(RIGHT(C15,2),1)="6","Cirebon",IF(LEFT(RIGHT(C15,2),1)="7","Tasik",IF(LEFT(RIGHT(C15,2),1)="8","Bogor",""))))) -> Cirebon | B15: =IF(LEFT(C15,2)="EL","Elektrik",IF(LEFT(C15,2)="PP","Pipa Pompa",IF(LEFT(C15,2)="IC","ICI",IF(LEFT(C15,2)="PI","Pipamas","")))) -> Elektrik | C15: ELSLE64 | D15: EKO YOGA PRAWIRA | E15: 45708 | G15: =VLOOKUP(Table7910111213[[#This Row],[Februari]],'Clean Data HR'!$G$2:$H$102,2,0) -> PMC2502002 | H15: 1342833637 | I15: EKO YOGA PRAWIRA | J15: =Table7910111213[[#This Row],[Februari]]=Table7910111213[[#This Row],[Data HR]] -> TRUE
A16: =IF(LEFT(RIGHT(C16,2),1)="0","Bandung",IF(LEFT(RIGHT(C16,2),1)="2","PCK",IF(LEFT(RIGHT(C16,2),1)="6","Cirebon",IF(LEFT(RIGHT(C16,2),1)="7","Tasik",IF(LEFT(RIGHT(C16,2),1)="8","Bogor",""))))) -> Cirebon | B16: =IF(LEFT(C16,2)="EL","Elektrik",IF(LEFT(C16,2)="PP","Pipa Pompa",IF(LEFT(C16,2)="IC","ICI",IF(LEFT(C16,2)="PI","Pipamas","")))) -> Elektrik | C16: ELSLE65 | D16: IPAN WIGUNA | E16: 45643 | G16: =VLOOKUP(Table7910111213[[#This Row],[Februari]],'Clean Data HR'!$G$2:$H$102,2,0) -> PMC2412003 | H16: 2991983084 | I16: IPAN WIGUNA | J16: =Table7910111213[[#This Row],[Februari]]=Table7910111213[[#This Row],[Data HR]] -> TRUE
A17: =IF(LEFT(RIGHT(C17,2),1)="0","Bandung",IF(LEFT(RIGHT(C17,2),1)="2","PCK",IF(LEFT(RIGHT(C17,2),1)="6","Cirebon",IF(LEFT(RIGHT(C17,2),1)="7","Tasik",IF(LEFT(RIGHT(C17,2),1)="8","Bogor",""))))) -> Tasik | B17: =IF(LEFT(C17,2)="EL","Elektrik",IF(LEFT(C17,2)="PP","Pipa Pompa",IF(LEFT(C17,2)="IC","ICI",IF(LEFT(C17,2)="PI","Pipamas","")))) -> Elektrik | C17: ELSLE71 | D17: FIRMANSYAH | E17: 45468 | G17: =VLOOKUP(Table7910111213[[#This Row],[Februari]],'Clean Data HR'!$G$2:$H$102,2,0) -> PMT2406003 | H17: 3211177428 | I17: FIRMANSYAH | J17: =Table7910111213[[#This Row],[Februari]]=Table7910111213[[#This Row],[Data HR]] -> TRUE
A18: =IF(LEFT(RIGHT(C18,2),1)="0","Bandung",IF(LEFT(RIGHT(C18,2),1)="2","PCK",IF(LEFT(RIGHT(C18,2),1)="6","Cirebon",IF(LEFT(RIGHT(C18,2),1)="7","Tasik",IF(LEFT(RIGHT(C18,2),1)="8","Bogor",""))))) -> Tasik | B18: =IF(LEFT(C18,2)="EL","Elektrik",IF(LEFT(C18,2)="PP","Pipa Pompa",IF(LEFT(C18,2)="IC","ICI",IF(LEFT(C18,2)="PI","Pipamas","")))) -> Elektrik | C18: ELSLE72 | D18: DHIA UL IMAN | E18: 44734 | G18: =VLOOKUP(Table7910111213[[#This Row],[Februari]],'Clean Data HR'!$G$2:$H$102,2,0) -> PMT2206001 | H18: 3210914411 | I18: DHIA UL IMAN | J18: =Table7910111213[[#This Row],[Februari]]=Table7910111213[[#This Row],[Data HR]] -> TRUE
A19: =IF(LEFT(RIGHT(C19,2),1)="0","Bandung",IF(LEFT(RIGHT(C19,2),1)="2","PCK",IF(LEFT(RIGHT(C19,2),1)="6","Cirebon",IF(LEFT(RIGHT(C19,2),1)="7","Tasik",IF(LEFT(RIGHT(C19,2),1)="8","Bogor",""))))) -> Tasik | B19: =IF(LEFT(C19,2)="EL","Elektrik",IF(LEFT(C19,2)="PP","Pipa Pompa",IF(LEFT(C19,2)="IC","ICI",IF(LEFT(C19,2)="PI","Pipamas","")))) -> Elektrik | C19: ELSLE73 | D19: VEBY RIZKY FAUZI | E19: 45558 | G19: =VLOOKUP(Table7910111213[[#This Row],[Februari]],'Clean Data HR'!$G$2:$H$102,2,0) -> PMT2409001 | H19: 0541384501 | I19: VEBY RIZKY FAUZI | J19: =Table7910111213[[#This Row],[Februari]]=Table7910111213[[#This Row],[Data HR]] -> TRUE
A20: =IF(LEFT(RIGHT(C20,2),1)="0","Bandung",IF(LEFT(RIGHT(C20,2),1)="2","PCK",IF(LEFT(RIGHT(C20,2),1)="6","Cirebon",IF(LEFT(RIGHT(C20,2),1)="7","Tasik",IF(LEFT(RIGHT(C20,2),1)="8","Bogor",""))))) -> Tasik | B20: =IF(LEFT(C20,2)="EL","Elektrik",IF(LEFT(C20,2)="PP","Pipa Pompa",IF(LEFT(C20,2)="IC","ICI",IF(LEFT(C20,2)="PI","Pipamas","")))) -> Elektrik | C20: ELSLE74 | D20: DIAN HAERANDI | E20: 45820 | G20: =VLOOKUP(Table7910111213[[#This Row],[Februari]],'Clean Data HR'!$G$2:$H$102,2,0) -> PMT2506001 | H20: 3211265807 | I20: DIAN HAERANDI | J20: =Table7910111213[[#This Row],[Februari]]=Table7910111213[[#This Row],[Data HR]] -> TRUE
A21: =IF(LEFT(RIGHT(C21,2),1)="0","Bandung",IF(LEFT(RIGHT(C21,2),1)="2","PCK",IF(LEFT(RIGHT(C21,2),1)="6","Cirebon",IF(LEFT(RIGHT(C21,2),1)="7","Tasik",IF(LEFT(RIGHT(C21,2),1)="8","Bogor",""))))) -> Tasik | B21: =IF(LEFT(C21,2)="EL","Elektrik",IF(LEFT(C21,2)="PP","Pipa Pompa",IF(LEFT(C21,2)="IC","ICI",IF(LEFT(C21,2)="PI","Pipamas","")))) -> Elektrik | C21: ELSLE75 | D21: JEJEN AL KOHIRI | E21: 45679 | G21: =VLOOKUP(Table7910111213[[#This Row],[Februari]],'Clean Data HR'!$G$2:$H$102,2,0) -> PMT2501001 | H21: 3210680810 | I21: JEJEN AL KOHIRI | J21: =Table7910111213[[#This Row],[Februari]]=Table7910111213[[#This Row],[Data HR]] -> TRUE
A22: =IF(LEFT(RIGHT(C22,2),1)="0","Bandung",IF(LEFT(RIGHT(C22,2),1)="2","PCK",IF(LEFT(RIGHT(C22,2),1)="6","Cirebon",IF(LEFT(RIGHT(C22,2),1)="7","Tasik",IF(LEFT(RIGHT(C22,2),1)="8","Bogor",""))))) -> Bogor | B22: =IF(LEFT(C22,2)="EL","Elektrik",IF(LEFT(C22,2)="PP","Pipa Pompa",IF(LEFT(C22,2)="IC","ICI",IF(LEFT(C22,2)="PI","Pipamas","")))) -> Elektrik | C22: ELSLE85 | D22: SYAHRI RIZKI | E22: 45414 | G22: =VLOOKUP(Table7910111213[[#This Row],[Februari]],'Clean Data HR'!$G$2:$H$102,2,0) -> PMB2405003 | H22: 3720066482 | I22: SYAHRI RIZKI | J22: =Table7910111213[[#This Row],[Februari]]=Table7910111213[[#This Row],[Data HR]] -> TRUE
A23: =IF(LEFT(RIGHT(C23,2),1)="0","Bandung",IF(LEFT(RIGHT(C23,2),1)="2","PCK",IF(LEFT(RIGHT(C23,2),1)="6","Cirebon",IF(LEFT(RIGHT(C23,2),1)="7","Tasik",IF(LEFT(RIGHT(C23,2),1)="8","Bogor",""))))) -> Bogor | B23: =IF(LEFT(C23,2)="EL","Elektrik",IF(LEFT(C23,2)="PP","Pipa Pompa",IF(LEFT(C23,2)="IC","ICI",IF(LEFT(C23,2)="PI","Pipamas","")))) -> Elektrik | C23: ELSLE86 | D23: WAHYU WIDIANA | E23: 44903 | G23: =VLOOKUP(Table7910111213[[#This Row],[Februari]],'Clean Data HR'!$G$2:$H$102,2,0) -> PMB2212002 | H23: 7402130230 | I23: WAHYU WIDIANA | J23: =Table7910111213[[#This Row],[Februari]]=Table7910111213[[#This Row],[Data HR]] -> TRUE
A24: =IF(LEFT(RIGHT(C24,2),1)="0","Bandung",IF(LEFT(RIGHT(C24,2),1)="2","PCK",IF(LEFT(RIGHT(C24,2),1)="6","Cirebon",IF(LEFT(RIGHT(C24,2),1)="7","Tasik",IF(LEFT(RIGHT(C24,2),1)="8","Bogor",""))))) -> Bogor | B24: =IF(LEFT(C24,2)="EL","Elektrik",IF(LEFT(C24,2)="PP","Pipa Pompa",IF(LEFT(C24,2)="IC","ICI",IF(LEFT(C24,2)="PI","Pipamas","")))) -> Elektrik | C24: ELSLE87 | D24: RYAN NOVI HANDOKO | E24: 44531 | G24: =VLOOKUP(Table7910111213[[#This Row],[Februari]],'Clean Data HR'!$G$2:$H$102,2,0) -> PMB2112002 | H24: 5015250876 | I24: RYAN NOVI HANDOKO | J24: =Table7910111213[[#This Row],[Februari]]=Table7910111213[[#This Row],[Data HR]] -> TRUE
A25: =IF(LEFT(RIGHT(C25,2),1)="0","Bandung",IF(LEFT(RIGHT(C25,2),1)="2","PCK",IF(LEFT(RIGHT(C25,2),1)="6","Cirebon",IF(LEFT(RIGHT(C25,2),1)="7","Tasik",IF(LEFT(RIGHT(C25,2),1)="8","Bogor",""))))) -> Bogor | B25: =IF(LEFT(C25,2)="EL","Elektrik",IF(LEFT(C25,2)="PP","Pipa Pompa",IF(LEFT(C25,2)="IC","ICI",IF(LEFT(C25,2)="PI","Pipamas","")))) -> Elektrik | C25: ELSLE88 | D25: MUHAMAD HASAN | E25: 44091 | G25: =VLOOKUP(Table7910111213[[#This Row],[Februari]],'Clean Data HR'!$G$2:$H$102,2,0) -> PMB2009005 | H25: 5735335861 | I25: MUHAMAD HASAN | J25: =Table7910111213[[#This Row],[Februari]]=Table7910111213[[#This Row],[Data HR]] -> TRUE
A26: =IF(LEFT(RIGHT(C26,2),1)="0","Bandung",IF(LEFT(RIGHT(C26,2),1)="2","PCK",IF(LEFT(RIGHT(C26,2),1)="6","Cirebon",IF(LEFT(RIGHT(C26,2),1)="7","Tasik",IF(LEFT(RIGHT(C26,2),1)="8","Bogor",""))))) -> Bogor | B26: =IF(LEFT(C26,2)="EL","Elektrik",IF(LEFT(C26,2)="PP","Pipa Pompa",IF(LEFT(C26,2)="IC","ICI",IF(LEFT(C26,2)="PI","Pipamas","")))) -> Elektrik | C26: ELSLE89 | D26: KRISNA ADI NUGRAHA | E26: 46066 | G26: =VLOOKUP(Table7910111213[[#This Row],[Februari]],'Clean Data HR'!$G$2:$H$102,2,0) -> PMD2602008 | H26: 8330055473 | I26: KRISNA ADI NUGRAHA | J26: =Table7910111213[[#This Row],[Februari]]=Table7910111213[[#This Row],[Data HR]] -> TRUE
A27: Bogor | B27: =IF(LEFT(C27,2)="EL","Elektrik",IF(LEFT(C27,2)="PP","Pipa Pompa",IF(LEFT(C27,2)="IC","ICI",IF(LEFT(C27,2)="PI","Pipamas","")))) -> Elektrik | C27: ELCOS08 | D27: ENDRIYANTO | E27: 44875 | G27: =VLOOKUP(Table7910111213[[#This Row],[Februari]],'Clean Data HR'!$G$2:$H$102,2,0) -> PMB2211002 | H27: 0380581647 | I27: ENDRIYANTO | J27: =Table7910111213[[#This Row],[Februari]]=Table7910111213[[#This Row],[Data HR]] -> TRUE
A28: Bogor | B28: =IF(LEFT(C28,2)="EL","Elektrik",IF(LEFT(C28,2)="PP","Pipa Pompa",IF(LEFT(C28,2)="IC","ICI",IF(LEFT(C28,2)="PI","Pipamas","")))) -> Elektrik | C28: ELSPV08 | D28: NANDA AMELIA | E28: 45414 | G28: =VLOOKUP(Table7910111213[[#This Row],[Februari]],'Clean Data HR'!$G$2:$H$102,2,0) -> PMB2405002 | H28: 0953571843 | I28: NANDA AMELIA | J28: =Table7910111213[[#This Row],[Februari]]=Table7910111213[[#This Row],[Data HR]] -> TRUE
A29: =IF(LEFT(RIGHT(C29,2),1)="0","Bandung",IF(LEFT(RIGHT(C29,2),1)="2","PCK",IF(LEFT(RIGHT(C29,2),1)="6","Cirebon",IF(LEFT(RIGHT(C29,2),1)="7","Tasik",IF(LEFT(RIGHT(C29,2),1)="8","Bogor",""))))) -> Bandung | B29: =IF(LEFT(C29,2)="EL","Elektrik",IF(LEFT(C29,2)="PP","Pipa Pompa",IF(LEFT(C29,2)="IC","ICI",IF(LEFT(C29,2)="PI","Pipamas","")))) -> ICI | C29: ICSLM01 | D29: IKHWAN FIDDIN | E29: 45139 | G29: =VLOOKUP(Table7910111213[[#This Row],[Februari]],'Clean Data HR'!$G$2:$H$102,2,0) -> PMD2308002 | H29: 2832258475 | I29: IKHWAN FIDDIN | J29: =Table7910111213[[#This Row],[Februari]]=Table7910111213[[#This Row],[Data HR]] -> TRUE
A30: =IF(LEFT(RIGHT(C30,2),1)="0","Bandung",IF(LEFT(RIGHT(C30,2),1)="2","PCK",IF(LEFT(RIGHT(C30,2),1)="6","Cirebon",IF(LEFT(RIGHT(C30,2),1)="7","Tasik",IF(LEFT(RIGHT(C30,2),1)="8","Bogor",""))))) -> Bandung | B30: =IF(LEFT(C30,2)="EL","Elektrik",IF(LEFT(C30,2)="PP","Pipa Pompa",IF(LEFT(C30,2)="IC","ICI",IF(LEFT(C30,2)="PI","Pipamas","")))) -> ICI | C30: ICSLM03 | D30: WAHYU RANGGA PERMANA | E30: 46057 | G30: =VLOOKUP(Table7910111213[[#This Row],[Februari]],'Clean Data HR'!$G$2:$H$102,2,0) -> PMD2602002 | H30: 7405373343 | I30: WAHYU RANGGA PERMANA | J30: =Table7910111213[[#This Row],[Februari]]=Table7910111213[[#This Row],[Data HR]] -> TRUE | K30: Pengganti Dadan Hardiansyah Putra
A31: =IF(LEFT(RIGHT(C31,2),1)="0","Bandung",IF(LEFT(RIGHT(C31,2),1)="2","PCK",IF(LEFT(RIGHT(C31,2),1)="6","Cirebon",IF(LEFT(RIGHT(C31,2),1)="7","Tasik",IF(LEFT(RIGHT(C31,2),1)="8","Bogor",""))))) -> Bandung | B31: =IF(LEFT(C31,2)="EL","Elektrik",IF(LEFT(C31,2)="PP","Pipa Pompa",IF(LEFT(C31,2)="IC","ICI",IF(LEFT(C31,2)="PI","Pipamas","")))) -> ICI | C31: ICSLM05 | D31: SATRIA PAMUNGKAS | E31: 44732 | G31: =VLOOKUP(Table7910111213[[#This Row],[Februari]],'Clean Data HR'!$G$2:$H$102,2,0) -> PMD2206002 | H31: 4372932876 | I31: SATRIA PAMUNGKAS | J31: =Table7910111213[[#This Row],[Februari]]=Table7910111213[[#This Row],[Data HR]] -> TRUE
A32: =IF(LEFT(RIGHT(C32,2),1)="0","Bandung",IF(LEFT(RIGHT(C32,2),1)="2","PCK",IF(LEFT(RIGHT(C32,2),1)="6","Cirebon",IF(LEFT(RIGHT(C32,2),1)="7","Tasik",IF(LEFT(RIGHT(C32,2),1)="8","Bogor",""))))) -> Bandung | B32: =IF(LEFT(C32,2)="EL","Elektrik",IF(LEFT(C32,2)="PP","Pipa Pompa",IF(LEFT(C32,2)="IC","ICI",IF(LEFT(C32,2)="PI","Pipamas","")))) -> ICI | C32: ICSLM06 | D32: RAHMAT HIDAYAT | E32: 44525 | G32: =VLOOKUP(Table7910111213[[#This Row],[Februari]],'Clean Data HR'!$G$2:$H$102,2,0) -> PMD2111013 | H32: 2830825579 | I32: RAHMAT HIDAYAT | J32: =Table7910111213[[#This Row],[Februari]]=Table7910111213[[#This Row],[Data HR]] -> TRUE
A33: =IF(LEFT(RIGHT(C33,2),1)="0","Bandung",IF(LEFT(RIGHT(C33,2),1)="2","PCK",IF(LEFT(RIGHT(C33,2),1)="6","Cirebon",IF(LEFT(RIGHT(C33,2),1)="7","Tasik",IF(LEFT(RIGHT(C33,2),1)="8","Bogor",""))))) -> Bandung | B33: =IF(LEFT(C33,2)="EL","Elektrik",IF(LEFT(C33,2)="PP","Pipa Pompa",IF(LEFT(C33,2)="IC","ICI",IF(LEFT(C33,2)="PI","Pipamas","")))) -> ICI | C33: ICSLM07 | D33: HARRY HAERUDIN, S.PD | E33: 43297 | G33: PMD1807011 | H33: 2831431212 | I33: HARRY HAERUDIN, S.PD | J33: =Table7910111213[[#This Row],[Februari]]=Table7910111213[[#This Row],[Data HR]] -> TRUE
A34: =IF(LEFT(RIGHT(C34,2),1)="0","Bandung",IF(LEFT(RIGHT(C34,2),1)="2","PCK",IF(LEFT(RIGHT(C34,2),1)="6","Cirebon",IF(LEFT(RIGHT(C34,2),1)="7","Tasik",IF(LEFT(RIGHT(C34,2),1)="8","Bogor",""))))) -> Bandung | B34: =IF(LEFT(C34,2)="EL","Elektrik",IF(LEFT(C34,2)="PP","Pipa Pompa",IF(LEFT(C34,2)="IC","ICI",IF(LEFT(C34,2)="PI","Pipamas","")))) -> ICI | C34: ICSLM08 | D34: MOCH ARMANDO VEBBY | E34: 44533 | G34: =VLOOKUP(Table7910111213[[#This Row],[Februari]],'Clean Data HR'!$G$2:$H$102,2,0) -> PMD2112004 | H34: 1393317101 | I34: MOCH ARMANDO VEBBY | J34: =Table7910111213[[#This Row],[Februari]]=Table7910111213[[#This Row],[Data HR]] -> TRUE
A35: =IF(LEFT(RIGHT(C35,2),1)="0","Bandung",IF(LEFT(RIGHT(C35,2),1)="2","PCK",IF(LEFT(RIGHT(C35,2),1)="6","Cirebon",IF(LEFT(RIGHT(C35,2),1)="7","Tasik",IF(LEFT(RIGHT(C35,2),1)="8","Bogor",""))))) -> Bandung | B35: =IF(LEFT(C35,2)="EL","Elektrik",IF(LEFT(C35,2)="PP","Pipa Pompa",IF(LEFT(C35,2)="IC","ICI",IF(LEFT(C35,2)="PI","Pipamas","")))) -> ICI | C35: ICSLM09 | D35: ANDI KURNIAWAN | E35: 44572 | G35: =VLOOKUP(Table7910111213[[#This Row],[Februari]],'Clean Data HR'!$G$2:$H$102,2,0) -> PMD2201008 | H35: 1760203960 | I35: ANDI KURNIAWAN | J35: =Table7910111213[[#This Row],[Februari]]=Table7910111213[[#This Row],[Data HR]] -> TRUE
A36: =IF(LEFT(RIGHT(C36,2),1)="0","Bandung",IF(LEFT(RIGHT(C36,2),1)="2","PCK",IF(LEFT(RIGHT(C36,2),1)="6","Cirebon",IF(LEFT(RIGHT(C36,2),1)="7","Tasik",IF(LEFT(RIGHT(C36,2),1)="8","Bogor",""))))) -> Bandung | B36: =IF(LEFT(C36,2)="EL","Elektrik",IF(LEFT(C36,2)="PP","Pipa Pompa",IF(LEFT(C36,2)="IC","ICI",IF(LEFT(C36,2)="PI","Pipamas","")))) -> ICI | C36: ICSLM09 | D36: ANTONIUS | E36: 46073 | G36: =VLOOKUP(Table7910111213[[#This Row],[Februari]],'Clean Data HR'!$G$2:$H$102,2,0) -> PMD2602010 | H36: 5150095231 | I36: ANTONIUS | J36: =Table7910111213[[#This Row],[Februari]]=Table7910111213[[#This Row],[Data HR]] -> TRUE
A37: =IF(LEFT(RIGHT(C37,2),1)="0","Bandung",IF(LEFT(RIGHT(C37,2),1)="2","PCK",IF(LEFT(RIGHT(C37,2),1)="6","Cirebon",IF(LEFT(RIGHT(C37,2),1)="7","Tasik",IF(LEFT(RIGHT(C37,2),1)="8","Bogor",""))))) -> PCK | B37: =IF(LEFT(C37,2)="EL","Elektrik",IF(LEFT(C37,2)="PP","Pipa Pompa",IF(LEFT(C37,2)="IC","ICI",IF(LEFT(C37,2)="PI","Pipamas","")))) -> ICI | C37: ICSLM21 | D37: UJANG SULAEMAN | E37: 44137 | G37: =VLOOKUP(Table7910111213[[#This Row],[Februari]],'Clean Data HR'!$G$2:$H$102,2,0) -> PMK2011003 | H37: 3780397925 | I37: UJANG SULAEMAN | J37: =Table7910111213[[#This Row],[Februari]]=Table7910111213[[#This Row],[Data HR]] -> TRUE
A38: =IF(LEFT(RIGHT(C38,2),1)="0","Bandung",IF(LEFT(RIGHT(C38,2),1)="2","PCK",IF(LEFT(RIGHT(C38,2),1)="6","Cirebon",IF(LEFT(RIGHT(C38,2),1)="7","Tasik",IF(LEFT(RIGHT(C38,2),1)="8","Bogor",""))))) -> PCK | B38: =IF(LEFT(C38,2)="EL","Elektrik",IF(LEFT(C38,2)="PP","Pipa Pompa",IF(LEFT(C38,2)="IC","ICI",IF(LEFT(C38,2)="PI","Pipamas","")))) -> ICI | C38: ICSLM22 | D38: AHMAD SANUSI | E38: 45894 | G38: =VLOOKUP(Table7910111213[[#This Row],[Februari]],'Clean Data HR'!$G$2:$H$102,2,0) -> PMD2508008 | H38: 5745718288 | I38: AHMAD SANUSI | J38: =Table7910111213[[#This Row],[Februari]]=Table7910111213[[#This Row],[Data HR]] -> TRUE
A39: =IF(LEFT(RIGHT(C39,2),1)="0","Bandung",IF(LEFT(RIGHT(C39,2),1)="2","PCK",IF(LEFT(RIGHT(C39,2),1)="6","Cirebon",IF(LEFT(RIGHT(C39,2),1)="7","Tasik",IF(LEFT(RIGHT(C39,2),1)="8","Bogor",""))))) -> PCK | B39: =IF(LEFT(C39,2)="EL","Elektrik",IF(LEFT(C39,2)="PP","Pipa Pompa",IF(LEFT(C39,2)="IC","ICI",IF(LEFT(C39,2)="PI","Pipamas","")))) -> ICI | C39: ICSLM23 | D39: BONAR JUMADA | E39: 43349 | G39: =VLOOKUP(Table7910111213[[#This Row],[Februari]],'Clean Data HR'!$G$2:$H$102,2,0) -> PMK1809003 | H39: 5770551341 | I39: BONAR JUMADA | J39: =Table7910111213[[#This Row],[Februari]]=Table7910111213[[#This Row],[Data HR]] -> TRUE
A40: =IF(LEFT(RIGHT(C40,2),1)="0","Bandung",IF(LEFT(RIGHT(C40,2),1)="2","PCK",IF(LEFT(RIGHT(C40,2),1)="6","Cirebon",IF(LEFT(RIGHT(C40,2),1)="7","Tasik",IF(LEFT(RIGHT(C40,2),1)="8","Bogor",""))))) -> PCK | B40: =IF(LEFT(C40,2)="EL","Elektrik",IF(LEFT(C40,2)="PP","Pipa Pompa",IF(LEFT(C40,2)="IC","ICI",IF(LEFT(C40,2)="PI","Pipamas","")))) -> ICI | C40: ICSLM28 | D40: ADHI GUSTIANA | E40: 43332 | G40: PMK1808008 | H40: 2310272283 | I40: ADHI GUSTIANA | J40: =Table7910111213[[#This Row],[Februari]]=Table7910111213[[#This Row],[Data HR]] -> TRUE
...

Sheet CLEAN
A1: Branch | B1: Divisi | C1: Kode Sales | D1: Februari | E1: Masuk | F1: Keluar | G1: NIK | H1: No Rek | I1: Sales Pengganti
A2: =IF(LEFT(RIGHT(C2,2),1)="0","Bandung",IF(LEFT(RIGHT(C2,2),1)="2","PCK",IF(LEFT(RIGHT(C2,2),1)="6","Cirebon",IF(LEFT(RIGHT(C2,2),1)="7","Tasik",IF(LEFT(RIGHT(C2,2),1)="8","Bogor",""))))) -> Bandung | B2: Elektrik | C2: SPVEL01 | D2: Martinus Laia | G2: PMD1610002 | H2: 4371830329
A3: =IF(LEFT(RIGHT(C3,2),1)="0","Bandung",IF(LEFT(RIGHT(C3,2),1)="2","PCK",IF(LEFT(RIGHT(C3,2),1)="6","Cirebon",IF(LEFT(RIGHT(C3,2),1)="7","Tasik",IF(LEFT(RIGHT(C3,2),1)="8","Bogor",""))))) -> Bandung | B3: =IF(LEFT(C3,2)="EL","Elektrik",IF(LEFT(C3,2)="PP","Pipa Pompa",IF(LEFT(C3,2)="IC","ICI",IF(LEFT(C3,2)="PI","Pipamas","")))) -> Elektrik | C3: ELMOD01 | D3: RIDWAN FAUZAN FIRDAUS | E3: 44588 | G3: =VLOOKUP(Table79101112133[[#This Row],[Februari]],'Clean Data HR'!$G$2:$H$102,2,0) -> PMD2201011 | H3: 4371314568
A4: =IF(LEFT(RIGHT(C4,2),1)="0","Bandung",IF(LEFT(RIGHT(C4,2),1)="2","PCK",IF(LEFT(RIGHT(C4,2),1)="6","Cirebon",IF(LEFT(RIGHT(C4,2),1)="7","Tasik",IF(LEFT(RIGHT(C4,2),1)="8","Bogor",""))))) -> Bandung | B4: =IF(LEFT(C4,2)="EL","Elektrik",IF(LEFT(C4,2)="PP","Pipa Pompa",IF(LEFT(C4,2)="IC","ICI",IF(LEFT(C4,2)="PI","Pipamas","")))) -> Elektrik | C4: ELMOD02 | D4: OKKY MAULANA EKWANUR | E4: 46058 | G4: PMD2602004 | H4: 0084433621
A5: =IF(LEFT(RIGHT(C5,2),1)="0","Bandung",IF(LEFT(RIGHT(C5,2),1)="2","PCK",IF(LEFT(RIGHT(C5,2),1)="6","Cirebon",IF(LEFT(RIGHT(C5,2),1)="7","Tasik",IF(LEFT(RIGHT(C5,2),1)="8","Bogor",""))))) -> Bandung | B5: =IF(LEFT(C5,2)="EL","Elektrik",IF(LEFT(C5,2)="PP","Pipa Pompa",IF(LEFT(C5,2)="IC","ICI",IF(LEFT(C5,2)="PI","Pipamas","")))) -> Elektrik | C5: ELSLE01 | D5: RENALDI AGUSTIANA YUSUF | E5: 46006 | G5: =VLOOKUP(Table79101112133[[#This Row],[Februari]],'Clean Data HR'!$G$2:$H$102,2,0) -> PMD2512008 | H5: 3741721129
A6: =IF(LEFT(RIGHT(C6,2),1)="0","Bandung",IF(LEFT(RIGHT(C6,2),1)="2","PCK",IF(LEFT(RIGHT(C6,2),1)="6","Cirebon",IF(LEFT(RIGHT(C6,2),1)="7","Tasik",IF(LEFT(RIGHT(C6,2),1)="8","Bogor",""))))) -> Bandung | B6: =IF(LEFT(C6,2)="EL","Elektrik",IF(LEFT(C6,2)="PP","Pipa Pompa",IF(LEFT(C6,2)="IC","ICI",IF(LEFT(C6,2)="PI","Pipamas","")))) -> Elektrik | C6: ELSLE02 | D6: SYAMSUL PALAH | E6: 45533 | G6: =VLOOKUP(Table79101112133[[#This Row],[Februari]],'Clean Data HR'!$G$2:$H$102,2,0) -> PMD2408006 | H6: 7940315390
A7: =IF(LEFT(RIGHT(C7,2),1)="0","Bandung",IF(LEFT(RIGHT(C7,2),1)="2","PCK",IF(LEFT(RIGHT(C7,2),1)="6","Cirebon",IF(LEFT(RIGHT(C7,2),1)="7","Tasik",IF(LEFT(RIGHT(C7,2),1)="8","Bogor",""))))) -> Bandung | B7: =IF(LEFT(C7,2)="EL","Elektrik",IF(LEFT(C7,2)="PP","Pipa Pompa",IF(LEFT(C7,2)="IC","ICI",IF(LEFT(C7,2)="PI","Pipamas","")))) -> Elektrik | C7: ELSLE03 | D7: GHISAN AL AZHALI | E7: 45628 | G7: =VLOOKUP(Table79101112133[[#This Row],[Februari]],'Clean Data HR'!$G$2:$H$102,2,0) -> PMD2412001 | H7: 7495077144
A8: =IF(LEFT(RIGHT(C8,2),1)="0","Bandung",IF(LEFT(RIGHT(C8,2),1)="2","PCK",IF(LEFT(RIGHT(C8,2),1)="6","Cirebon",IF(LEFT(RIGHT(C8,2),1)="7","Tasik",IF(LEFT(RIGHT(C8,2),1)="8","Bogor",""))))) -> Bandung | B8: =IF(LEFT(C8,2)="EL","Elektrik",IF(LEFT(C8,2)="PP","Pipa Pompa",IF(LEFT(C8,2)="IC","ICI",IF(LEFT(C8,2)="PI","Pipamas","")))) -> Elektrik | C8: ELSLE04 | D8: VIRSQI INDRA PERDANA | E8: 46000 | G8: =VLOOKUP(Table79101112133[[#This Row],[Februari]],'Clean Data HR'!$G$2:$H$102,2,0) -> PMD2512005 | H8: 1390637132
A9: =IF(LEFT(RIGHT(C9,2),1)="0","Bandung",IF(LEFT(RIGHT(C9,2),1)="2","PCK",IF(LEFT(RIGHT(C9,2),1)="6","Cirebon",IF(LEFT(RIGHT(C9,2),1)="7","Tasik",IF(LEFT(RIGHT(C9,2),1)="8","Bogor",""))))) -> Bandung | B9: =IF(LEFT(C9,2)="EL","Elektrik",IF(LEFT(C9,2)="PP","Pipa Pompa",IF(LEFT(C9,2)="IC","ICI",IF(LEFT(C9,2)="PI","Pipamas","")))) -> Elektrik | C9: ELSLE05 | D9: HASUDUNGAN | E9: 44704 | G9: =VLOOKUP(Table79101112133[[#This Row],[Februari]],'Clean Data HR'!$G$2:$H$102,2,0) -> PMD2205003 | H9: 2810384045
A10: =IF(LEFT(RIGHT(C10,2),1)="0","Bandung",IF(LEFT(RIGHT(C10,2),1)="2","PCK",IF(LEFT(RIGHT(C10,2),1)="6","Cirebon",IF(LEFT(RIGHT(C10,2),1)="7","Tasik",IF(LEFT(RIGHT(C10,2),1)="8","Bogor",""))))) -> Bandung | B10: =IF(LEFT(C10,2)="EL","Elektrik",IF(LEFT(C10,2)="PP","Pipa Pompa",IF(LEFT(C10,2)="IC","ICI",IF(LEFT(C10,2)="PI","Pipamas","")))) -> Elektrik | C10: ELCOS01 | D10: NUR ALI | E10: 44706 | G10: =VLOOKUP(Table79101112133[[#This Row],[Februari]],'Clean Data HR'!$G$2:$H$102,2,0) -> PMD2205006 | H10: 8100893330
A11: =IF(LEFT(RIGHT(C11,2),1)="0","Bandung",IF(LEFT(RIGHT(C11,2),1)="2","PCK",IF(LEFT(RIGHT(C11,2),1)="6","Cirebon",IF(LEFT(RIGHT(C11,2),1)="7","Tasik",IF(LEFT(RIGHT(C11,2),1)="8","Bogor",""))))) -> PCK | B11: =IF(LEFT(C11,2)="EL","Elektrik",IF(LEFT(C11,2)="PP","Pipa Pompa",IF(LEFT(C11,2)="IC","ICI",IF(LEFT(C11,2)="PI","Pipamas","")))) -> Elektrik | C11: ELSLE25 | D11: KIKI HADISURYA | E11: 45649 | G11: =VLOOKUP(Table79101112133[[#This Row],[Februari]],'Clean Data HR'!$G$2:$H$102,2,0) -> PMK2412001 | H11: 0087042531
A12: =IF(LEFT(RIGHT(C12,2),1)="0","Bandung",IF(LEFT(RIGHT(C12,2),1)="2","PCK",IF(LEFT(RIGHT(C12,2),1)="6","Cirebon",IF(LEFT(RIGHT(C12,2),1)="7","Tasik",IF(LEFT(RIGHT(C12,2),1)="8","Bogor",""))))) -> Cirebon | B12: =IF(LEFT(C12,2)="EL","Elektrik",IF(LEFT(C12,2)="PP","Pipa Pompa",IF(LEFT(C12,2)="IC","ICI",IF(LEFT(C12,2)="PI","Pipamas","")))) -> Elektrik | C12: ELSLE60 | D12: NURFADILAH | E12: 44951 | G12: =VLOOKUP(Table79101112133[[#This Row],[Februari]],'Clean Data HR'!$G$2:$H$102,2,0) -> PMC2301001 | H12: 1342293292
A13: =IF(LEFT(RIGHT(C13,2),1)="0","Bandung",IF(LEFT(RIGHT(C13,2),1)="2","PCK",IF(LEFT(RIGHT(C13,2),1)="6","Cirebon",IF(LEFT(RIGHT(C13,2),1)="7","Tasik",IF(LEFT(RIGHT(C13,2),1)="8","Bogor",""))))) -> Cirebon | B13: =IF(LEFT(C13,2)="EL","Elektrik",IF(LEFT(C13,2)="PP","Pipa Pompa",IF(LEFT(C13,2)="IC","ICI",IF(LEFT(C13,2)="PI","Pipamas","")))) -> Elektrik | C13: ELSLE61 | D13: FANJI BERLIANDY AZHARI RIDZKI | E13: 44536 | G13: =VLOOKUP(Table79101112133[[#This Row],[Februari]],'Clean Data HR'!$G$2:$H$102,2,0) -> PMC2112006 | H13: 8180224085
A14: =IF(LEFT(RIGHT(C14,2),1)="0","Bandung",IF(LEFT(RIGHT(C14,2),1)="2","PCK",IF(LEFT(RIGHT(C14,2),1)="6","Cirebon",IF(LEFT(RIGHT(C14,2),1)="7","Tasik",IF(LEFT(RIGHT(C14,2),1)="8","Bogor",""))))) -> Cirebon | B14: =IF(LEFT(C14,2)="EL","Elektrik",IF(LEFT(C14,2)="PP","Pipa Pompa",IF(LEFT(C14,2)="IC","ICI",IF(LEFT(C14,2)="PI","Pipamas","")))) -> Elektrik | C14: ELSLE62 | D14: ADE TRIHANDOYO | E14: 45845 | G14: PMC2507002 | H14: 373802651
A15: =IF(LEFT(RIGHT(C15,2),1)="0","Bandung",IF(LEFT(RIGHT(C15,2),1)="2","PCK",IF(LEFT(RIGHT(C15,2),1)="6","Cirebon",IF(LEFT(RIGHT(C15,2),1)="7","Tasik",IF(LEFT(RIGHT(C15,2),1)="8","Bogor",""))))) -> Cirebon | B15: =IF(LEFT(C15,2)="EL","Elektrik",IF(LEFT(C15,2)="PP","Pipa Pompa",IF(LEFT(C15,2)="IC","ICI",IF(LEFT(C15,2)="PI","Pipamas","")))) -> Elektrik | C15: ELSLE63 | D15: FIDYAH FAROID | E15: 45502 | G15: =VLOOKUP(Table79101112133[[#This Row],[Februari]],'Clean Data HR'!$G$2:$H$102,2,0) -> PMC2407004 | H15: 8180505475
A16: =IF(LEFT(RIGHT(C16,2),1)="0","Bandung",IF(LEFT(RIGHT(C16,2),1)="2","PCK",IF(LEFT(RIGHT(C16,2),1)="6","Cirebon",IF(LEFT(RIGHT(C16,2),1)="7","Tasik",IF(LEFT(RIGHT(C16,2),1)="8","Bogor",""))))) -> Cirebon | B16: =IF(LEFT(C16,2)="EL","Elektrik",IF(LEFT(C16,2)="PP","Pipa Pompa",IF(LEFT(C16,2)="IC","ICI",IF(LEFT(C16,2)="PI","Pipamas","")))) -> Elektrik | C16: ELSLE64 | D16: EKO YOGA PRAWIRA | E16: 45708 | G16: =VLOOKUP(Table79101112133[[#This Row],[Februari]],'Clean Data HR'!$G$2:$H$102,2,0) -> PMC2502002 | H16: 1342833637
A17: =IF(LEFT(RIGHT(C17,2),1)="0","Bandung",IF(LEFT(RIGHT(C17,2),1)="2","PCK",IF(LEFT(RIGHT(C17,2),1)="6","Cirebon",IF(LEFT(RIGHT(C17,2),1)="7","Tasik",IF(LEFT(RIGHT(C17,2),1)="8","Bogor",""))))) -> Cirebon | B17: =IF(LEFT(C17,2)="EL","Elektrik",IF(LEFT(C17,2)="PP","Pipa Pompa",IF(LEFT(C17,2)="IC","ICI",IF(LEFT(C17,2)="PI","Pipamas","")))) -> Elektrik | C17: ELSLE65 | D17: IPAN WIGUNA | E17: 45643 | G17: =VLOOKUP(Table79101112133[[#This Row],[Februari]],'Clean Data HR'!$G$2:$H$102,2,0) -> PMC2412003 | H17: 2991983084
A18: =IF(LEFT(RIGHT(C18,2),1)="0","Bandung",IF(LEFT(RIGHT(C18,2),1)="2","PCK",IF(LEFT(RIGHT(C18,2),1)="6","Cirebon",IF(LEFT(RIGHT(C18,2),1)="7","Tasik",IF(LEFT(RIGHT(C18,2),1)="8","Bogor",""))))) -> Tasik | B18: =IF(LEFT(C18,2)="EL","Elektrik",IF(LEFT(C18,2)="PP","Pipa Pompa",IF(LEFT(C18,2)="IC","ICI",IF(LEFT(C18,2)="PI","Pipamas","")))) -> Elektrik | C18: ELSLE71 | D18: FIRMANSYAH | E18: 45468 | G18: =VLOOKUP(Table79101112133[[#This Row],[Februari]],'Clean Data HR'!$G$2:$H$102,2,0) -> PMT2406003 | H18: 3211177428
A19: =IF(LEFT(RIGHT(C19,2),1)="0","Bandung",IF(LEFT(RIGHT(C19,2),1)="2","PCK",IF(LEFT(RIGHT(C19,2),1)="6","Cirebon",IF(LEFT(RIGHT(C19,2),1)="7","Tasik",IF(LEFT(RIGHT(C19,2),1)="8","Bogor",""))))) -> Tasik | B19: =IF(LEFT(C19,2)="EL","Elektrik",IF(LEFT(C19,2)="PP","Pipa Pompa",IF(LEFT(C19,2)="IC","ICI",IF(LEFT(C19,2)="PI","Pipamas","")))) -> Elektrik | C19: ELSLE72 | D19: DHIA UL IMAN | E19: 44734 | G19: =VLOOKUP(Table79101112133[[#This Row],[Februari]],'Clean Data HR'!$G$2:$H$102,2,0) -> PMT2206001 | H19: 3210914411
A20: =IF(LEFT(RIGHT(C20,2),1)="0","Bandung",IF(LEFT(RIGHT(C20,2),1)="2","PCK",IF(LEFT(RIGHT(C20,2),1)="6","Cirebon",IF(LEFT(RIGHT(C20,2),1)="7","Tasik",IF(LEFT(RIGHT(C20,2),1)="8","Bogor",""))))) -> Tasik | B20: =IF(LEFT(C20,2)="EL","Elektrik",IF(LEFT(C20,2)="PP","Pipa Pompa",IF(LEFT(C20,2)="IC","ICI",IF(LEFT(C20,2)="PI","Pipamas","")))) -> Elektrik | C20: ELSLE73 | D20: VEBY RIZKY FAUZI | E20: 45558 | G20: =VLOOKUP(Table79101112133[[#This Row],[Februari]],'Clean Data HR'!$G$2:$H$102,2,0) -> PMT2409001 | H20: 0541384501
A21: =IF(LEFT(RIGHT(C21,2),1)="0","Bandung",IF(LEFT(RIGHT(C21,2),1)="2","PCK",IF(LEFT(RIGHT(C21,2),1)="6","Cirebon",IF(LEFT(RIGHT(C21,2),1)="7","Tasik",IF(LEFT(RIGHT(C21,2),1)="8","Bogor",""))))) -> Tasik | B21: =IF(LEFT(C21,2)="EL","Elektrik",IF(LEFT(C21,2)="PP","Pipa Pompa",IF(LEFT(C21,2)="IC","ICI",IF(LEFT(C21,2)="PI","Pipamas","")))) -> Elektrik | C21: ELSLE74 | D21: DIAN HAERANDI | E21: 45820 | G21: =VLOOKUP(Table79101112133[[#This Row],[Februari]],'Clean Data HR'!$G$2:$H$102,2,0) -> PMT2506001 | H21: 3211265807
A22: =IF(LEFT(RIGHT(C22,2),1)="0","Bandung",IF(LEFT(RIGHT(C22,2),1)="2","PCK",IF(LEFT(RIGHT(C22,2),1)="6","Cirebon",IF(LEFT(RIGHT(C22,2),1)="7","Tasik",IF(LEFT(RIGHT(C22,2),1)="8","Bogor",""))))) -> Tasik | B22: =IF(LEFT(C22,2)="EL","Elektrik",IF(LEFT(C22,2)="PP","Pipa Pompa",IF(LEFT(C22,2)="IC","ICI",IF(LEFT(C22,2)="PI","Pipamas","")))) -> Elektrik | C22: ELSLE75 | D22: JEJEN AL KOHIRI | E22: 45679 | G22: =VLOOKUP(Table79101112133[[#This Row],[Februari]],'Clean Data HR'!$G$2:$H$102,2,0) -> PMT2501001 | H22: 3210680810
A23: =IF(LEFT(RIGHT(C23,2),1)="0","Bandung",IF(LEFT(RIGHT(C23,2),1)="2","PCK",IF(LEFT(RIGHT(C23,2),1)="6","Cirebon",IF(LEFT(RIGHT(C23,2),1)="7","Tasik",IF(LEFT(RIGHT(C23,2),1)="8","Bogor",""))))) -> Bogor | B23: =IF(LEFT(C23,2)="EL","Elektrik",IF(LEFT(C23,2)="PP","Pipa Pompa",IF(LEFT(C23,2)="IC","ICI",IF(LEFT(C23,2)="PI","Pipamas","")))) -> Elektrik | C23: ELSLE85 | D23: SYAHRI RIZKI | E23: 45414 | G23: =VLOOKUP(Table79101112133[[#This Row],[Februari]],'Clean Data HR'!$G$2:$H$102,2,0) -> PMB2405003 | H23: 3720066482
A24: =IF(LEFT(RIGHT(C24,2),1)="0","Bandung",IF(LEFT(RIGHT(C24,2),1)="2","PCK",IF(LEFT(RIGHT(C24,2),1)="6","Cirebon",IF(LEFT(RIGHT(C24,2),1)="7","Tasik",IF(LEFT(RIGHT(C24,2),1)="8","Bogor",""))))) -> Bogor | B24: =IF(LEFT(C24,2)="EL","Elektrik",IF(LEFT(C24,2)="PP","Pipa Pompa",IF(LEFT(C24,2)="IC","ICI",IF(LEFT(C24,2)="PI","Pipamas","")))) -> Elektrik | C24: ELSLE86 | D24: WAHYU WIDIANA | E24: 44903 | G24: =VLOOKUP(Table79101112133[[#This Row],[Februari]],'Clean Data HR'!$G$2:$H$102,2,0) -> PMB2212002 | H24: 7402130230
A25: =IF(LEFT(RIGHT(C25,2),1)="0","Bandung",IF(LEFT(RIGHT(C25,2),1)="2","PCK",IF(LEFT(RIGHT(C25,2),1)="6","Cirebon",IF(LEFT(RIGHT(C25,2),1)="7","Tasik",IF(LEFT(RIGHT(C25,2),1)="8","Bogor",""))))) -> Bogor | B25: =IF(LEFT(C25,2)="EL","Elektrik",IF(LEFT(C25,2)="PP","Pipa Pompa",IF(LEFT(C25,2)="IC","ICI",IF(LEFT(C25,2)="PI","Pipamas","")))) -> Elektrik | C25: ELSLE87 | D25: RYAN NOVI HANDOKO | E25: 44531 | G25: =VLOOKUP(Table79101112133[[#This Row],[Februari]],'Clean Data HR'!$G$2:$H$102,2,0) -> PMB2112002 | H25: 5015250876
A26: =IF(LEFT(RIGHT(C26,2),1)="0","Bandung",IF(LEFT(RIGHT(C26,2),1)="2","PCK",IF(LEFT(RIGHT(C26,2),1)="6","Cirebon",IF(LEFT(RIGHT(C26,2),1)="7","Tasik",IF(LEFT(RIGHT(C26,2),1)="8","Bogor",""))))) -> Bogor | B26: =IF(LEFT(C26,2)="EL","Elektrik",IF(LEFT(C26,2)="PP","Pipa Pompa",IF(LEFT(C26,2)="IC","ICI",IF(LEFT(C26,2)="PI","Pipamas","")))) -> Elektrik | C26: ELSLE88 | D26: MUHAMAD HASAN | E26: 44091 | G26: =VLOOKUP(Table79101112133[[#This Row],[Februari]],'Clean Data HR'!$G$2:$H$102,2,0) -> PMB2009005 | H26: 5735335861
A27: =IF(LEFT(RIGHT(C27,2),1)="0","Bandung",IF(LEFT(RIGHT(C27,2),1)="2","PCK",IF(LEFT(RIGHT(C27,2),1)="6","Cirebon",IF(LEFT(RIGHT(C27,2),1)="7","Tasik",IF(LEFT(RIGHT(C27,2),1)="8","Bogor",""))))) -> Bogor | B27: =IF(LEFT(C27,2)="EL","Elektrik",IF(LEFT(C27,2)="PP","Pipa Pompa",IF(LEFT(C27,2)="IC","ICI",IF(LEFT(C27,2)="PI","Pipamas","")))) -> Elektrik | C27: ELSLE89 | D27: KRISNA ADI NUGRAHA | E27: 46066 | G27: =VLOOKUP(Table79101112133[[#This Row],[Februari]],'Clean Data HR'!$G$2:$H$102,2,0) -> PMD2602008 | H27: 8330055473
A28: Bogor | B28: =IF(LEFT(C28,2)="EL","Elektrik",IF(LEFT(C28,2)="PP","Pipa Pompa",IF(LEFT(C28,2)="IC","ICI",IF(LEFT(C28,2)="PI","Pipamas","")))) -> Elektrik | C28: ELCOS08 | D28: ENDRIYANTO | E28: 44875 | G28: =VLOOKUP(Table79101112133[[#This Row],[Februari]],'Clean Data HR'!$G$2:$H$102,2,0) -> PMB2211002 | H28: 0380581647
A29: Bogor | B29: =IF(LEFT(C29,2)="EL","Elektrik",IF(LEFT(C29,2)="PP","Pipa Pompa",IF(LEFT(C29,2)="IC","ICI",IF(LEFT(C29,2)="PI","Pipamas","")))) -> Elektrik | C29: ELSPV08 | D29: NANDA AMELIA | E29: 45414 | G29: =VLOOKUP(Table79101112133[[#This Row],[Februari]],'Clean Data HR'!$G$2:$H$102,2,0) -> PMB2405002 | H29: 0953571843
A30: =IF(LEFT(RIGHT(C30,2),1)="0","Bandung",IF(LEFT(RIGHT(C30,2),1)="2","PCK",IF(LEFT(RIGHT(C30,2),1)="6","Cirebon",IF(LEFT(RIGHT(C30,2),1)="7","Tasik",IF(LEFT(RIGHT(C30,2),1)="8","Bogor",""))))) -> Bandung | B30: =IF(LEFT(C30,2)="EL","Elektrik",IF(LEFT(C30,2)="PP","Pipa Pompa",IF(LEFT(C30,2)="IC","ICI",IF(LEFT(C30,2)="PI","Pipamas","")))) -> ICI | C30: ICSLM01 | D30: IKHWAN FIDDIN | E30: 45139 | G30: =VLOOKUP(Table79101112133[[#This Row],[Februari]],'Clean Data HR'!$G$2:$H$102,2,0) -> PMD2308002 | H30: 2832258475
A31: =IF(LEFT(RIGHT(C31,2),1)="0","Bandung",IF(LEFT(RIGHT(C31,2),1)="2","PCK",IF(LEFT(RIGHT(C31,2),1)="6","Cirebon",IF(LEFT(RIGHT(C31,2),1)="7","Tasik",IF(LEFT(RIGHT(C31,2),1)="8","Bogor",""))))) -> Bandung | B31: =IF(LEFT(C31,2)="EL","Elektrik",IF(LEFT(C31,2)="PP","Pipa Pompa",IF(LEFT(C31,2)="IC","ICI",IF(LEFT(C31,2)="PI","Pipamas","")))) -> ICI | C31: ICSLM03 | D31: WAHYU RANGGA PERMANA | E31: 46057 | G31: =VLOOKUP(Table79101112133[[#This Row],[Februari]],'Clean Data HR'!$G$2:$H$102,2,0) -> PMD2602002 | H31: 7405373343 | I31: Pengganti Dadan Hardiansyah Putra Keluar tgl 2/2/2026
A32: =IF(LEFT(RIGHT(C32,2),1)="0","Bandung",IF(LEFT(RIGHT(C32,2),1)="2","PCK",IF(LEFT(RIGHT(C32,2),1)="6","Cirebon",IF(LEFT(RIGHT(C32,2),1)="7","Tasik",IF(LEFT(RIGHT(C32,2),1)="8","Bogor",""))))) -> Bandung | B32: =IF(LEFT(C32,2)="EL","Elektrik",IF(LEFT(C32,2)="PP","Pipa Pompa",IF(LEFT(C32,2)="IC","ICI",IF(LEFT(C32,2)="PI","Pipamas","")))) -> ICI | C32: ICSLM05 | D32: SATRIA PAMUNGKAS | E32: 44732 | G32: =VLOOKUP(Table79101112133[[#This Row],[Februari]],'Clean Data HR'!$G$2:$H$102,2,0) -> PMD2206002 | H32: 4372932876
A33: =IF(LEFT(RIGHT(C33,2),1)="0","Bandung",IF(LEFT(RIGHT(C33,2),1)="2","PCK",IF(LEFT(RIGHT(C33,2),1)="6","Cirebon",IF(LEFT(RIGHT(C33,2),1)="7","Tasik",IF(LEFT(RIGHT(C33,2),1)="8","Bogor",""))))) -> Bandung | B33: =IF(LEFT(C33,2)="EL","Elektrik",IF(LEFT(C33,2)="PP","Pipa Pompa",IF(LEFT(C33,2)="IC","ICI",IF(LEFT(C33,2)="PI","Pipamas","")))) -> ICI | C33: ICSLM06 | D33: RAHMAT HIDAYAT | E33: 44525 | G33: =VLOOKUP(Table79101112133[[#This Row],[Februari]],'Clean Data HR'!$G$2:$H$102,2,0) -> PMD2111013 | H33: 2830825579
A34: =IF(LEFT(RIGHT(C34,2),1)="0","Bandung",IF(LEFT(RIGHT(C34,2),1)="2","PCK",IF(LEFT(RIGHT(C34,2),1)="6","Cirebon",IF(LEFT(RIGHT(C34,2),1)="7","Tasik",IF(LEFT(RIGHT(C34,2),1)="8","Bogor",""))))) -> Bandung | B34: =IF(LEFT(C34,2)="EL","Elektrik",IF(LEFT(C34,2)="PP","Pipa Pompa",IF(LEFT(C34,2)="IC","ICI",IF(LEFT(C34,2)="PI","Pipamas","")))) -> ICI | C34: ICSLM07 | D34: HARRY HAERUDIN, S.PD | E34: 43297 | G34: PMD1807011 | H34: 2831431212
A35: =IF(LEFT(RIGHT(C35,2),1)="0","Bandung",IF(LEFT(RIGHT(C35,2),1)="2","PCK",IF(LEFT(RIGHT(C35,2),1)="6","Cirebon",IF(LEFT(RIGHT(C35,2),1)="7","Tasik",IF(LEFT(RIGHT(C35,2),1)="8","Bogor",""))))) -> Bandung | B35: =IF(LEFT(C35,2)="EL","Elektrik",IF(LEFT(C35,2)="PP","Pipa Pompa",IF(LEFT(C35,2)="IC","ICI",IF(LEFT(C35,2)="PI","Pipamas","")))) -> ICI | C35: ICSLM08 | D35: MOCH ARMANDO VEBBY | E35: 44533 | G35: =VLOOKUP(Table79101112133[[#This Row],[Februari]],'Clean Data HR'!$G$2:$H$102,2,0) -> PMD2112004 | H35: 1393317101
A36: =IF(LEFT(RIGHT(C36,2),1)="0","Bandung",IF(LEFT(RIGHT(C36,2),1)="2","PCK",IF(LEFT(RIGHT(C36,2),1)="6","Cirebon",IF(LEFT(RIGHT(C36,2),1)="7","Tasik",IF(LEFT(RIGHT(C36,2),1)="8","Bogor",""))))) -> Bandung | B36: =IF(LEFT(C36,2)="EL","Elektrik",IF(LEFT(C36,2)="PP","Pipa Pompa",IF(LEFT(C36,2)="IC","ICI",IF(LEFT(C36,2)="PI","Pipamas","")))) -> ICI | C36: ICSLM09 | D36: ANDI KURNIAWAN | E36: 44572 | G36: =VLOOKUP(Table79101112133[[#This Row],[Februari]],'Clean Data HR'!$G$2:$H$102,2,0) -> PMD2201008 | H36: 1760203960
A37: =IF(LEFT(RIGHT(C37,2),1)="0","Bandung",IF(LEFT(RIGHT(C37,2),1)="2","PCK",IF(LEFT(RIGHT(C37,2),1)="6","Cirebon",IF(LEFT(RIGHT(C37,2),1)="7","Tasik",IF(LEFT(RIGHT(C37,2),1)="8","Bogor",""))))) -> Bandung | B37: =IF(LEFT(C37,2)="EL","Elektrik",IF(LEFT(C37,2)="PP","Pipa Pompa",IF(LEFT(C37,2)="IC","ICI",IF(LEFT(C37,2)="PI","Pipamas","")))) -> ICI | C37: ICSLM09 | D37: ANTONIUS | E37: 46073 | G37: =VLOOKUP(Table79101112133[[#This Row],[Februari]],'Clean Data HR'!$G$2:$H$102,2,0) -> PMD2602010 | H37: 5150095231
A38: =IF(LEFT(RIGHT(C38,2),1)="0","Bandung",IF(LEFT(RIGHT(C38,2),1)="2","PCK",IF(LEFT(RIGHT(C38,2),1)="6","Cirebon",IF(LEFT(RIGHT(C38,2),1)="7","Tasik",IF(LEFT(RIGHT(C38,2),1)="8","Bogor",""))))) -> PCK | B38: =IF(LEFT(C38,2)="EL","Elektrik",IF(LEFT(C38,2)="PP","Pipa Pompa",IF(LEFT(C38,2)="IC","ICI",IF(LEFT(C38,2)="PI","Pipamas","")))) -> ICI | C38: ICSLM21 | D38: UJANG SULAEMAN | E38: 44137 | G38: =VLOOKUP(Table79101112133[[#This Row],[Februari]],'Clean Data HR'!$G$2:$H$102,2,0) -> PMK2011003 | H38: 3780397925
A39: =IF(LEFT(RIGHT(C39,2),1)="0","Bandung",IF(LEFT(RIGHT(C39,2),1)="2","PCK",IF(LEFT(RIGHT(C39,2),1)="6","Cirebon",IF(LEFT(RIGHT(C39,2),1)="7","Tasik",IF(LEFT(RIGHT(C39,2),1)="8","Bogor",""))))) -> PCK | B39: =IF(LEFT(C39,2)="EL","Elektrik",IF(LEFT(C39,2)="PP","Pipa Pompa",IF(LEFT(C39,2)="IC","ICI",IF(LEFT(C39,2)="PI","Pipamas","")))) -> ICI | C39: ICSLM22 | D39: AHMAD SANUSI | E39: 45894 | G39: =VLOOKUP(Table79101112133[[#This Row],[Februari]],'Clean Data HR'!$G$2:$H$102,2,0) -> PMD2508008 | H39: 5745718288
A40: =IF(LEFT(RIGHT(C40,2),1)="0","Bandung",IF(LEFT(RIGHT(C40,2),1)="2","PCK",IF(LEFT(RIGHT(C40,2),1)="6","Cirebon",IF(LEFT(RIGHT(C40,2),1)="7","Tasik",IF(LEFT(RIGHT(C40,2),1)="8","Bogor",""))))) -> PCK | B40: =IF(LEFT(C40,2)="EL","Elektrik",IF(LEFT(C40,2)="PP","Pipa Pompa",IF(LEFT(C40,2)="IC","ICI",IF(LEFT(C40,2)="PI","Pipamas","")))) -> ICI | C40: ICSLM23 | D40: BONAR JUMADA | E40: 43349 | G40: =VLOOKUP(Table79101112133[[#This Row],[Februari]],'Clean Data HR'!$G$2:$H$102,2,0) -> PMK1809003 | H40: 5770551341
...

Sheet Clean Data HR
A1: St | B1: FIX | C1: Nu | D1: NIK | E1: Lama Kerja | F1: No AC | G1: Dept and Location | H1: NIK | I1: Tgl Resign | J1: Posisi | K1: Tgl Masuk | L1: Agama | M1: Tgl Lahir | N1: Keterangan
A2: ST | B2: NO | C2: 1 | D2: PMD2207003 | E2: =((YEAR(TODAY())-YEAR(K2))*12+MONTH(TODAY())-MONTH(K2))/12 -> 2.8333333 | F2: 1560107931 | G2: RICKI GALIH GINANJAR | H2: PMD2207003 | J2: Coordinator Sales Pipamas Division | K2: 45169 | L2: Islam | M2: 32129 | P2: =VLOOKUP(D2,'[1]0524'!$B$3:$B$125,1,0) -> PMD2207003
A3: ST | B3: NO | C3: 2 | D3: PMD2109007 | E3: =((YEAR(TODAY())-YEAR(K3))*12+MONTH(TODAY())-MONTH(K3))/12 -> 4.75 | F3: 2831290783 | G3: MUHAMMAD RIKI SAFARI | H3: PMD2109007 | J3: Sales Pipamas Staff Soekarno Hatta | K3: 44460 | L3: Islam | M3: 34894 | P3: =VLOOKUP(D3,'[1]0524'!$B$3:$B$125,1,0) -> PMD2109007
A4: ST | B4: NO | C4: 3 | D4: PMD2210008 | E4: =((YEAR(TODAY())-YEAR(K4))*12+MONTH(TODAY())-MONTH(K4))/12 -> 3.6666667 | F4: 0083879235 | G4: BAGUS GUMILAR | H4: PMD2210008 | J4: Sales Pipamas Staff Soekarno Hatta | K4: 44858 | L4: Islam | M4: 34577 | P4: =VLOOKUP(D4,'[1]0524'!$B$3:$B$125,1,0) -> PMD2210008
A5: ST | B5: NO | C5: 4 | D5: PMD2503003 | E5: =((YEAR(TODAY())-YEAR(K5))*12+MONTH(TODAY())-MONTH(K5))/12 -> 1.25 | F5: 7750965185 | G5: ADITYA MUHAMMAD RAMDHAN | H5: PMD2503003 | J5: Sales Pipamas Staff Soekarno Hatta | K5: 45727 | L5: Islam | M5: 34391
A6: ST | B6: NO | C6: 5 | D6: PMD2503004 | E6: =((YEAR(TODAY())-YEAR(K6))*12+MONTH(TODAY())-MONTH(K6))/12 -> 1.25 | F6: 1560108695 | G6: GUGUN HANAFI | H6: PMD2503004 | J6: Sales Pipamas Staff Soekarno Hatta | K6: 45727 | L6: Islam | M6: 35744
A7: ST | B7: NO | C7: 6 | D7: PMD2505002 | E7: =((YEAR(TODAY())-YEAR(K7))*12+MONTH(TODAY())-MONTH(K7))/12 -> 1.0833333 | F7: 4310478577 | G7: ANRE IKHSAN ROSYADI | H7: PMD2505002 | I7: 46091 | J7: Sales Pipamas Staff Soekarno Hatta | K7: 45792 | L7: Islam | M7: 32585
A8: ST | B8: NO | C8: 7 | D8: PMD2508004 | E8: =((YEAR(TODAY())-YEAR(K8))*12+MONTH(TODAY())-MONTH(K8))/12 -> 0.83333333 | F8: 8320689768 | G8: IKHSAN MAULANA YUSUF | H8: PMD2508004 | J8: Sales Pipamas Staff Soekarno Hatta | K8: 45887 | L8: Islam | M8: 34699
A9: ST | B9: NO | C9: 8 | D9: PMD2508010 | E9: =((YEAR(TODAY())-YEAR(K9))*12+MONTH(TODAY())-MONTH(K9))/12 -> 0.83333333 | F9: 3790592777 | G9: ASEP SOPIYAN | H9: PMD2508010 | J9: Sales Pipamas Staff Soekarno Hatta | K9: 45896 | L9: Islam | M9: 30738
A10: ST | B10: NO | C10: 9 | D10: PMD2509003 | E10: =((YEAR(TODAY())-YEAR(K10))*12+MONTH(TODAY())-MONTH(K10))/12 -> 0.75 | F10: 2800939910 | G10: HARI WIHARYANA | H10: PMD2509003 | J10: Sales Pipamas Staff Soekarno Hatta | K10: 45904 | L10: Islam | M10: 29291
A11: ST | B11: NO | C11: 10 | D11: PMD2512006 | E11: =((YEAR(TODAY())-YEAR(K11))*12+MONTH(TODAY())-MONTH(K11))/12 -> 0.5 | F11: 8090609018 | G11: BILLY SUGIARTO | H11: PMD2512006 | J11: Coordinator Sales Pipamas Division | K11: 46000 | L11: Islam | M11: 33910
A12: ST | B12: NO | C12: 11 | D12: PMD2512003 | E12: =((YEAR(TODAY())-YEAR(K12))*12+MONTH(TODAY())-MONTH(K12))/12 -> 0.5 | F12: 4461503378 | G12: RIZAL ZAELANI | H12: PMD2512003 | J12: Sales Pipamas Staff Soekarno Hatta | K12: 45996 | L12: Islam | M12: 33210
A13: ST | B13: NO | C13: 1 | D13: PMD2201011 | E13: =((YEAR(TODAY())-YEAR(K13))*12+MONTH(TODAY())-MONTH(K13))/12 -> 4.4166667 | F13: 4371314568 | G13: RIDWAN FAUZAN FIRDAUS | H13: PMD2201011 | J13: Sales Electric Staff Soekarno Hatta | K13: 44588 | L13: Islam | M13: 34627 | P13: =VLOOKUP(D31,'[1]0524'!$B$3:$B$125,1,0) -> PMD2308002
A14: ST | B14: NO | C14: 2 | D14: PMD2205003 | E14: =((YEAR(TODAY())-YEAR(K14))*12+MONTH(TODAY())-MONTH(K14))/12 -> 4.0833333 | F14: 2810384045 | G14: HASUDUNGAN | H14: PMD2205003 | J14: Sales Electric Staff Soekarno Hatta | K14: 44704 | L14: Islam | M14: 31148 | P14: =VLOOKUP(#REF!,'[1]0524'!$B$3:$B$125,1,0) -> #REF!
A15: ST | B15: NO | C15: 3 | D15: PMD2408006 | E15: =((YEAR(TODAY())-YEAR(K15))*12+MONTH(TODAY())-MONTH(K15))/12 -> 1.8333333 | F15: 7940315390 | G15: SYAMSUL PALAH | H15: PMD2408006 | J15: Sales Electric Staff Soekarno Hatta | K15: 45533 | L15: Islam | M15: 36568
A16: ST | B16: NO | C16: 4 | D16: PMD2412001 | E16: =((YEAR(TODAY())-YEAR(K16))*12+MONTH(TODAY())-MONTH(K16))/12 -> 1.5 | F16: 7495077144 | G16: GHISAN AL AZHALI | H16: PMD2412001 | J16: Sales Electric Staff Soekarno Hatta | K16: 45628 | L16: Islam | M16: 33840
A17: ST | B17: NO | C17: 5 | D17: PMD2512005 | E17: =((YEAR(TODAY())-YEAR(K17))*12+MONTH(TODAY())-MONTH(K17))/12 -> 0.5 | F17: 1390637132 | G17: VIRSQI INDRA PERDANA | H17: PMD2512005 | J17: Sales Electric Staff Soekarno Hatta | K17: 46000 | L17: Islam | M17: 34636
A18: ST | B18: NO | C18: 6 | D18: PMD2512008 | E18: =((YEAR(TODAY())-YEAR(K18))*12+MONTH(TODAY())-MONTH(K18))/12 -> 0.5 | F18: 3741721129 | G18: RENALDI AGUSTIANA YUSUF | H18: PMD2512008 | J18: Sales Electric Staff Soekarno Hatta | K18: 46006 | L18: Islam | M18: 36032
A19: ST | B19: NO | C19: 1 | D19: PMD2012002 | E19: =((YEAR(TODAY())-YEAR(K19))*12+MONTH(TODAY())-MONTH(K19))/12 -> 5.5 | F19: 0631281850 | G19: ASTON VILLA | H19: PMD2012002 | I19: 46125 | J19: Sales Coordinator Pipe & Pump Division Soekarno Hatta | K19: 44172 | L19: Islam | M19: 31221 | N19: HOLD | P19: =VLOOKUP(#REF!,'[1]0524'!$B$3:$B$125,1,0) -> #REF!
A20: ST | B20: NO | C20: 2 | D20: PMD2402001 | E20: =((YEAR(TODAY())-YEAR(K20))*12+MONTH(TODAY())-MONTH(K20))/12 -> 2.3333333 | F20: 8103039361 | G20: AGUS GUNAWAN | H20: PMD2402001 | J20: Sales Pipe & Pump Staff Soekarno Hatta | K20: 45334 | L20: Islam | M20: 32768 | P20: =VLOOKUP(#REF!,'[1]0524'!$B$3:$B$125,1,0) -> #REF!
A21: ST | B21: NO | C21: 3 | D21: PMD2407002 | E21: =((YEAR(TODAY())-YEAR(K21))*12+MONTH(TODAY())-MONTH(K21))/12 -> 1.9166667 | F21: 1760287934 | G21: ANDRE SETIAWAN | H21: PMD2407002 | J21: Sales Pipe & Pump Staff Soekarno Hatta | K21: 45481 | L21: Islam | M21: 35959
A22: ST | B22: NO | C22: 4 | D22: PMD2502005 | E22: =((YEAR(TODAY())-YEAR(K22))*12+MONTH(TODAY())-MONTH(K22))/12 -> 1.3333333 | F22: 2801445111 | G22: ERLAN SOPIANA | H22: PMD2502005 | J22: Sales Pipe & Pump Staff Soekarno Hatta | K22: 45713 | L22: Islam | M22: 35233
A23: ST | B23: NO | C23: 5 | D23: PMD2506001 | E23: =((YEAR(TODAY())-YEAR(K23))*12+MONTH(TODAY())-MONTH(K23))/12 -> 1 | F23: 8106058160 | G23: HENDIKUS WARUWU | H23: PMD2506001 | I23: 46111 | J23: Sales Pipe & Pump Staff Soekarno Hatta | K23: 45838 | L23: Katolik | M23: 37450
A24: ST | B24: NO | C24: 6 | D24: PMD2107003 | E24: =((YEAR(TODAY())-YEAR(K24))*12+MONTH(TODAY())-MONTH(K24))/12 -> 4.9166667 | F24: 2830811802 | G24: YUS YUSUF ANGGA SETIABUDI | H24: PMD2107003 | J24: Sales Pipe & Pump Staff Soekarno Hatta | K24: 44403 | L24: Islam | M24: 32155
A25: ST | B25: NO | C25: 8 | D25: PMD2511002 | E25: =((YEAR(TODAY())-YEAR(K25))*12+MONTH(TODAY())-MONTH(K25))/12 -> 0.58333333 | F25: 2831900280 | G25: TEGOEH PRAMONO | H25: PMD2511002 | J25: Sales Pipe & Pump Staff Soekarno Hatta | K25: 45978 | L25: Islam | M25: 31614
A26: ST | B26: NO | C26: 9 | D26: PMD2511004 | E26: =((YEAR(TODAY())-YEAR(K26))*12+MONTH(TODAY())-MONTH(K26))/12 -> 0.58333333 | F26: 1392396947 | G26: LEO FERDIANSYAH | H26: PMD2511004 | J26: Sales Pipe & Pump Staff Soekarno Hatta | K26: 45979 | L26: Islam | M26: 31274
A27: ST | B27: NO | C27: 1 | D27: PMD2111013 | E27: =((YEAR(TODAY())-YEAR(K27))*12+MONTH(TODAY())-MONTH(K27))/12 -> 4.5833333 | F27: 2830825579 | G27: RAHMAT HIDAYAT | H27: PMD2111013 | J27: Sales Paint Staff Soekarno Hatta | K27: 44525 | L27: Islam | M27: 27249 | P27: =VLOOKUP(#REF!,'[1]0524'!$B$3:$B$125,1,0) -> #REF!
A28: ST | B28: NO | C28: 2 | D28: PMD2112004 | E28: =((YEAR(TODAY())-YEAR(K28))*12+MONTH(TODAY())-MONTH(K28))/12 -> 4.5 | F28: 1393317101 | G28: MOCH ARMANDO VEBBY | H28: PMD2112004 | J28: Sales Supervisor Paint Staff Soekarno Hatta | K28: 44533 | L28: Islam | M28: 32685 | P28: =VLOOKUP(#REF!,'[1]0524'!$B$3:$B$125,1,0) -> #REF!
A29: ST | B29: NO | C29: 3 | D29: PMD2201008 | E29: =((YEAR(TODAY())-YEAR(K29))*12+MONTH(TODAY())-MONTH(K29))/12 -> 4.4166667 | F29: 1760203960 | G29: ANDI KURNIAWAN | H29: PMD2201008 | J29: Sales Paint Staff Soekarno Hatta | K29: 44572 | L29: Islam | M29: 32726 | P29: =VLOOKUP(D27,'[1]0524'!$B$3:$B$125,1,0) -> PMD2111013
A30: ST | B30: NO | C30: 4 | D30: PMD2206002 | E30: =((YEAR(TODAY())-YEAR(K30))*12+MONTH(TODAY())-MONTH(K30))/12 -> 4 | F30: 4372932876 | G30: SATRIA PAMUNGKAS | H30: PMD2206002 | J30: Sales Coordinator Paint Division | K30: 44732 | L30: Islam | M30: 29884 | P30: =VLOOKUP(#REF!,'[1]0524'!$B$3:$B$125,1,0) -> #REF!
A31: ST | B31: NO | C31: 5 | D31: PMD2308002 | E31: =((YEAR(TODAY())-YEAR(K31))*12+MONTH(TODAY())-MONTH(K31))/12 -> 2.8333333 | F31: 2832258475 | G31: IKHWAN FIDDIN | H31: PMD2308002 | I31: 46136 | J31: Sales Paint Staff Soekarno Hatta | K31: 45139 | L31: Islam | M31: 33909 | N31: HOLD | P31: =VLOOKUP(D28,'[1]0524'!$B$3:$B$125,1,0) -> #N/A
A32: ST | B32: NO | C32: 6 | D32: PMD2602002 | E32: =((YEAR(TODAY())-YEAR(K32))*12+MONTH(TODAY())-MONTH(K32))/12 -> 0.33333333 | F32: 7405373343 | G32: WAHYU RANGGA PERMANA | H32: PMD2602002 | J32: Sales Paint Staff Soekarno Hatta | K32: 46057 | L32: Islam | M32: 32046
A33: ST | B33: NO | C33: 7 | D33: PMD2602010 | E33: =((YEAR(TODAY())-YEAR(K33))*12+MONTH(TODAY())-MONTH(K33))/12 -> 0.33333333 | F33: 5150095231 | G33: ANTONIUS | H33: PMD2602010 | J33: Sales Powertools Staff Soekarno Hatta | K33: 46073 | L33: Islam | M33: 31175
A34: ST | B34: NO | C34: 1 | D34: PMD2205006 | E34: =((YEAR(TODAY())-YEAR(K34))*12+MONTH(TODAY())-MONTH(K34))/12 -> 4.0833333 | F34: 8100893330 | G34: NUR ALI | H34: PMD2205006 | J34: Sales Coordinator Electric Soekarno Hatta | K34: 44706 | L34: Islam | M34: 35135 | P34: =VLOOKUP(#REF!,'[1]0524'!$B$3:$B$125,1,0) -> #REF!
A35: ST | B35: NO | C35: 1 | D35: PMB2506001 | E35: =((YEAR(TODAY())-YEAR(K35))*12+MONTH(TODAY())-MONTH(K35))/12 -> 1 | F35: 7380496873 | G35: RAMLI NASUTION | H35: PMB2506001 | I35: 46146 | J35: Sales ICI Coordinator Bogor | K35: 45817 | L35: Islam | M35: 30054 | N35: HOLD
A36: ST | B36: NO | C36: 2 | D36: PMB1909012 | E36: =((YEAR(TODAY())-YEAR(K36))*12+MONTH(TODAY())-MONTH(K36))/12 -> 6.75 | F36: 3370017751 | G36: LUCKY GEMA CHRISTYAN SYAH | H36: PMB1909012 | J36: Sales ICI Staff Bogor | K36: 43731 | L36: Islam | M36: 33253 | P36: =VLOOKUP(#REF!,'[1]0524'!$B$3:$B$125,1,0) -> #REF!
A37: ST | B37: NO | C37: 3 | D37: PMB2105004 | E37: =((YEAR(TODAY())-YEAR(K37))*12+MONTH(TODAY())-MONTH(K37))/12 -> 5.0833333 | F37: 8720710197 | G37: ZAENUDIN | H37: PMB2105004 | J37: Sales ICI Staff Bogor | K37: 44341 | L37: Islam | M37: 32708 | P37: =VLOOKUP(#REF!,'[1]0524'!$B$3:$B$125,1,0) -> #REF!
A38: ST | B38: NO | C38: 4 | D38: PMB2405006 | E38: =((YEAR(TODAY())-YEAR(K38))*12+MONTH(TODAY())-MONTH(K38))/12 -> 2.0833333 | F38: 0953412346 | G38: ASEP PERMANA NOOR | H38: PMB2405006 | J38: Sales ICI Staff Bogor | K38: 45426 | L38: Islam | M38: 31565
A39: ST | B39: NO | C39: 5 | D39: PMB2411002 | E39: =((YEAR(TODAY())-YEAR(K39))*12+MONTH(TODAY())-MONTH(K39))/12 -> 1.5833333 | F39: 1672882235 | G39: FAJAR NUGRAHA | H39: PMB2411002 | J39: Sales ICI Staff Bogor | K39: 45616 | L39: Islam | M39: 34033
A40: ST | B40: NO | C40: 6 | D40: PMD2509001 | E40: =((YEAR(TODAY())-YEAR(K40))*12+MONTH(TODAY())-MONTH(K40))/12 -> 0.75 | F40: 6820539786 | G40: ZAINAL HAKIKI | H40: PMD2509001 | J40: Sales ICI Supervisor Bogor | K40: 45901 | L40: Islam | M40: 34609
...

Sheet Karyawan Resign
A1: Karyawan Sudah Resign
A2: ST | B2: NO | C2: 1 | D2: PMD2201006 | H2: =((YEAR(TODAY())-YEAR(M2))*12+MONTH(TODAY())-MONTH(M2))/12 -> 4.4166667 | I2: 1393356867 | J2: Dadan Hardiansah Putra | K2: 46055 | L2: Sales Paint Staff Soekarno Hatta | M2: 44572 | N2: Islam | O2: 29884
A3: ST | B3: NO | C3: 2 | D3: PMB2411001 | H3: =((YEAR(TODAY())-YEAR(M3))*12+MONTH(TODAY())-MONTH(M3))/12 -> 1.5833333 | I3: 0954790581 | J3: Antonio Rifaldo | K3: 46058 | L3: Sales Pipe & Pump Staff Bogor | M3: 45607 | N3: Islam | O3: 44683
A4: ST | B4: NO | C4: 3 | D4: PMT2010001 | H4: =((YEAR(TODAY())-YEAR(M4))*12+MONTH(TODAY())-MONTH(M4))/12 -> 5.6666667 | I4: 0541428037 | J4: Rudi Ruswandi | K4: 46055 | L4: Sales Pipamas Staff Tasikmalaya | M4: 44106 | N4: Islam | O4: 31104
A5: ST | B5: NO | C5: 4 | D5: PMD2601002 | H5: =((YEAR(TODAY())-YEAR(M5))*12+MONTH(TODAY())-MONTH(M5))/12 -> 0.41666667 | I5: 6610706418 | J5: Fitrah Ramadhan | K5: 46071 | L5: Sales ICI Staff Bogor | M5: 46051 | N5: Islam | O5: 35117

Sheet 20an
A1: PT. Pancamas Pipasakti - Periode 1 - 28 Februari 2026 (Salesman)
E3: S | F3: I / C | G3: A
A4: St | B4: FIX | C4: Nu | D4: NIK | F4: ABSEN | H4: Lama Kerja | I4: No AC | J4: Dept and Location | K4: Tgl Resign | L4: Posisi | M4: Tgl Masuk | N4: Agama | O4: Tgl Lahir | P4: Keterangan
J5: ALL Divisi Bandung
J6: Marketing Online
A7: ST | B7: NO | C7: 1 | D7: PMD2002003 | H7: =((YEAR(TODAY())-YEAR(M7))*12+MONTH(TODAY())-MONTH(M7))/12 -> 6.3333333 | I7: 2801307991 | J7: Fanny Aisiyah Zuliani | L7: Coordinator Marketing Online Departement Soekarno Hatta | M7: 43865 | N7: Islam | O7: 32350 | Q7: =VLOOKUP(J7,'[2]PT Pipamas Primasejati'!$G:$G,1,0) -> FANNY AISIYAH ZULIANI
A8: ST | B8: NO | C8: 2 | D8: PMD2408004 | H8: =((YEAR(TODAY())-YEAR(M8))*12+MONTH(TODAY())-MONTH(M8))/12 -> 1.8333333 | I8: 3790895125 | J8: Enok Rina Hasanah | L8: Marketing Online Departement Soekarno Hatta | M8: 45513 | N8: Islam | O8: 35872
A9: ST | B9: NO | C9: 3 | D9: PMD2502003 | H9: =((YEAR(TODAY())-YEAR(M9))*12+MONTH(TODAY())-MONTH(M9))/12 -> 1.3333333 | I9: 7753136314 | J9: Yuli Sartika | L9: Marketing Online Departement Soekarno Hatta | M9: 45705 | N9: Islam | O9: 35635
J11: Pipamas Bandung
J12: Sales Pipamas
A13: ST | B13: NO | C13: 1 | D13: PMD2207003 | H13: =((YEAR(TODAY())-YEAR(M13))*12+MONTH(TODAY())-MONTH(M13))/12 -> 2.8333333 | I13: 1560107931 | J13: Ricki Galih Ginanjar | L13: Coordinator Sales Pipamas Division | M13: 45169 | N13: Islam | O13: 32129 | R13: =VLOOKUP(D13,'[1]0524'!$B$3:$B$125,1,0) -> PMD2207003
A14: ST | B14: NO | C14: 2 | D14: PMD2109007 | H14: =((YEAR(TODAY())-YEAR(M14))*12+MONTH(TODAY())-MONTH(M14))/12 -> 4.75 | I14: 2831290783 | J14: Muhammad Riki Safari | L14: Sales Pipamas Staff Soekarno Hatta | M14: 44460 | N14: Islam | O14: 34894 | R14: =VLOOKUP(D14,'[1]0524'!$B$3:$B$125,1,0) -> PMD2109007
A15: ST | B15: NO | C15: 3 | D15: PMD2210008 | H15: =((YEAR(TODAY())-YEAR(M15))*12+MONTH(TODAY())-MONTH(M15))/12 -> 3.6666667 | I15: 0083879235 | J15: Bagus Gumilar | L15: Sales Pipamas Staff Soekarno Hatta | M15: 44858 | N15: Islam | O15: 34577 | R15: =VLOOKUP(D15,'[1]0524'!$B$3:$B$125,1,0) -> PMD2210008
A16: ST | B16: NO | C16: 4 | D16: PMD2503003 | H16: =((YEAR(TODAY())-YEAR(M16))*12+MONTH(TODAY())-MONTH(M16))/12 -> 1.25 | I16: 7750965185 | J16: Aditya Muhammad Ramdhan | L16: Sales Pipamas Staff Soekarno Hatta | M16: 45727 | N16: Islam | O16: 34391
A17: ST | B17: NO | C17: 5 | D17: PMD2503004 | H17: =((YEAR(TODAY())-YEAR(M17))*12+MONTH(TODAY())-MONTH(M17))/12 -> 1.25 | I17: 1560108695 | J17: Gugun Hanafi | L17: Sales Pipamas Staff Soekarno Hatta | M17: 45727 | N17: Islam | O17: 35744
A18: ST | B18: NO | C18: 6 | D18: PMD2505002 | H18: =((YEAR(TODAY())-YEAR(M18))*12+MONTH(TODAY())-MONTH(M18))/12 -> 1.0833333 | I18: 4310478577 | J18: Anre Ikhsan Rosyadi | K18: 46091 | L18: Sales Pipamas Staff Soekarno Hatta | M18: 45792 | N18: Islam | O18: 32585
A19: ST | B19: NO | C19: 7 | D19: PMD2508004 | H19: =((YEAR(TODAY())-YEAR(M19))*12+MONTH(TODAY())-MONTH(M19))/12 -> 0.83333333 | I19: 8320689768 | J19: Ikhsan Maulana Yusuf | L19: Sales Pipamas Staff Soekarno Hatta | M19: 45887 | N19: Islam | O19: 34699
A20: ST | B20: NO | C20: 8 | D20: PMD2508010 | H20: =((YEAR(TODAY())-YEAR(M20))*12+MONTH(TODAY())-MONTH(M20))/12 -> 0.83333333 | I20: 3790592777 | J20: Asep Sopiyan | L20: Sales Pipamas Staff Soekarno Hatta | M20: 45896 | N20: Islam | O20: 30738
