Workbook

Sheet 20an
A1: St | B1: FIX | C1: Nu | D1: NIK | E1: Sakit | F1: Izin | G1: Alpha | H1: Lama Kerja | I1: No AC | J1: Dept and Location | K1: Tgl Resign | L1: Posisi | M1: Tgl Masuk | N1: Agama | O1: Tgl Lahir | P1: Keterangan | Q1: Rekonsiliasi
A2: ST | B2: NO | C2: 1 | D2: PMD2002003 | E2: 0 | F2: 0 | G2: 0 | H2: =((YEAR(TODAY())-YEAR(M2))*12+MONTH(TODAY())-MONTH(M2))/12 -> 6.25 | I2: 2801307991 | J2: Fanny Aisiyah Zuliani | L2: Coordinator Marketing Online Departement Soekarno Hatta | M2: 43865 | N2: Islam | O2: 32350 | Q2: =IF(COUNTIF('JAN26'!$G:$G, D2)=0, "Tidak Ada", "Ada") -> Tidak Ada
A3: ST | B3: NO | C3: 2 | D3: PMD2408004 | E3: 0 | F3: 0 | G3: 0 | H3: =((YEAR(TODAY())-YEAR(M3))*12+MONTH(TODAY())-MONTH(M3))/12 -> 1.75 | I3: 3790895125 | J3: Enok Rina Hasanah | L3: Marketing Online Departement Soekarno Hatta | M3: 45513 | N3: Islam | O3: 35872 | Q3: =IF(COUNTIF('JAN26'!$G:$G, D3)=0, "Tidak Ada", "Ada") -> Tidak Ada
A4: ST | B4: NO | C4: 3 | D4: PMD2502003 | E4: 1 | F4: 0 | G4: 0 | H4: =((YEAR(TODAY())-YEAR(M4))*12+MONTH(TODAY())-MONTH(M4))/12 -> 1.25 | I4: 7753136314 | J4: Yuli Sartika | L4: Marketing Online Departement Soekarno Hatta | M4: 45705 | N4: Islam | O4: 35635 | Q4: =IF(COUNTIF('JAN26'!$G:$G, D4)=0, "Tidak Ada", "Ada") -> Tidak Ada
A5: ST | B5: NO | C5: 1 | D5: PMD2207003 | E5: 0 | F5: 0 | G5: 0 | H5: =((YEAR(TODAY())-YEAR(M5))*12+MONTH(TODAY())-MONTH(M5))/12 -> 2.75 | I5: 1560107931 | J5: Ricki Galih Ginanjar | L5: Coordinator Sales Pipamas Division | M5: 45169 | N5: Islam | O5: 32129 | Q5: =IF(COUNTIF('JAN26'!$G:$G, D5)=0, "Tidak Ada", "Ada") -> Ada
A6: ST | B6: NO | C6: 2 | D6: PMD2109007 | E6: 0 | F6: 0 | G6: 0 | H6: =((YEAR(TODAY())-YEAR(M6))*12+MONTH(TODAY())-MONTH(M6))/12 -> 4.6666667 | I6: 2831290783 | J6: Muhammad Riki Safari | L6: Sales Pipamas Staff Soekarno Hatta | M6: 44460 | N6: Islam | O6: 34894 | Q6: =IF(COUNTIF('JAN26'!$G:$G, D6)=0, "Tidak Ada", "Ada") -> Ada
A7: ST | B7: NO | C7: 3 | D7: PMD2210008 | E7: 1 | F7: 0 | G7: 0 | H7: =((YEAR(TODAY())-YEAR(M7))*12+MONTH(TODAY())-MONTH(M7))/12 -> 3.5833333 | I7: 0083879235 | J7: Bagus Gumilar | L7: Sales Pipamas Staff Soekarno Hatta | M7: 44858 | N7: Islam | O7: 34577 | Q7: =IF(COUNTIF('JAN26'!$G:$G, D7)=0, "Tidak Ada", "Ada") -> Ada
A8: ST | B8: NO | C8: 4 | D8: PMD2503003 | E8: 0 | F8: 0 | G8: 0 | H8: =((YEAR(TODAY())-YEAR(M8))*12+MONTH(TODAY())-MONTH(M8))/12 -> 1.1666667 | I8: 7750965185 | J8: Aditya Muhammad Ramdhan | L8: Sales Pipamas Staff Soekarno Hatta | M8: 45727 | N8: Islam | O8: 34391 | Q8: =IF(COUNTIF('JAN26'!$G:$G, D8)=0, "Tidak Ada", "Ada") -> Ada
A9: ST | B9: NO | C9: 5 | D9: PMD2503004 | E9: 0 | F9: 0 | G9: 0 | H9: =((YEAR(TODAY())-YEAR(M9))*12+MONTH(TODAY())-MONTH(M9))/12 -> 1.1666667 | I9: 1560108695 | J9: Gugun Hanafi | L9: Sales Pipamas Staff Soekarno Hatta | M9: 45727 | N9: Islam | O9: 35744 | Q9: =IF(COUNTIF('JAN26'!$G:$G, D9)=0, "Tidak Ada", "Ada") -> Ada
A10: ST | B10: NO | C10: 6 | D10: PMD2505002 | E10: 0 | F10: 0 | G10: 1 | H10: =((YEAR(TODAY())-YEAR(M10))*12+MONTH(TODAY())-MONTH(M10))/12 -> 1 | I10: 4310478577 | J10: Anre Ikhsan Rosyadi | K10: 46091 | L10: Sales Pipamas Staff Soekarno Hatta | M10: 45792 | N10: Islam | O10: 32585 | Q10: =IF(COUNTIF('JAN26'!$G:$G, D10)=0, "Tidak Ada", "Ada") -> Ada
A11: ST | B11: NO | C11: 7 | D11: PMD2508004 | E11: 0 | F11: 3 | G11: 0 | H11: =((YEAR(TODAY())-YEAR(M11))*12+MONTH(TODAY())-MONTH(M11))/12 -> 0.75 | I11: 8320689768 | J11: Ikhsan Maulana Yusuf | L11: Sales Pipamas Staff Soekarno Hatta | M11: 45887 | N11: Islam | O11: 34699 | Q11: =IF(COUNTIF('JAN26'!$G:$G, D11)=0, "Tidak Ada", "Ada") -> Ada
A12: ST | B12: NO | C12: 8 | D12: PMD2508010 | E12: 0 | F12: 0 | G12: 0 | H12: =((YEAR(TODAY())-YEAR(M12))*12+MONTH(TODAY())-MONTH(M12))/12 -> 0.75 | I12: 3790592777 | J12: Asep Sopiyan | L12: Sales Pipamas Staff Soekarno Hatta | M12: 45896 | N12: Islam | O12: 30738 | Q12: =IF(COUNTIF('JAN26'!$G:$G, D12)=0, "Tidak Ada", "Ada") -> Ada
A13: ST | B13: NO | C13: 9 | D13: PMD2509003 | E13: 0 | F13: 0 | G13: 0 | H13: =((YEAR(TODAY())-YEAR(M13))*12+MONTH(TODAY())-MONTH(M13))/12 -> 0.66666667 | I13: 2800939910 | J13: Hari Wiharyana | L13: Sales Pipamas Staff Soekarno Hatta | M13: 45904 | N13: Islam | O13: 29291 | Q13: =IF(COUNTIF('JAN26'!$G:$G, D13)=0, "Tidak Ada", "Ada") -> Ada
A14: ST | B14: NO | C14: 10 | D14: PMD2512006 | E14: 0 | F14: 0 | G14: 0 | H14: =((YEAR(TODAY())-YEAR(M14))*12+MONTH(TODAY())-MONTH(M14))/12 -> 0.41666667 | I14: 8090609018 | J14: Billy Sugiarto | L14: Coordinator Sales Pipamas Division | M14: 46000 | N14: Islam | O14: 33910 | Q14: =IF(COUNTIF('JAN26'!$G:$G, D14)=0, "Tidak Ada", "Ada") -> Ada
A15: ST | B15: NO | C15: 1 | D15: PMD2205003 | E15: 0 | F15: 0 | G15: 0 | H15: =((YEAR(TODAY())-YEAR(M15))*12+MONTH(TODAY())-MONTH(M15))/12 -> 4 | I15: 2810384045 | J15: Hasudungan | L15: Sales Electric Staff Soekarno Hatta | M15: 44704 | N15: Islam | O15: 31148 | Q15: =IF(COUNTIF('JAN26'!$G:$G, D15)=0, "Tidak Ada", "Ada") -> Ada
A16: ST | B16: NO | C16: 2 | D16: PMD2408006 | E16: 0 | F16: 0 | G16: 0 | H16: =((YEAR(TODAY())-YEAR(M16))*12+MONTH(TODAY())-MONTH(M16))/12 -> 1.75 | I16: 7940315390 | J16: Syamsul Palah | L16: Sales Electric Staff Soekarno Hatta | M16: 45533 | N16: Islam | O16: 36568 | Q16: =IF(COUNTIF('JAN26'!$G:$G, D16)=0, "Tidak Ada", "Ada") -> Ada
A17: ST | B17: NO | C17: 3 | D17: PMD2412001 | E17: 0 | F17: 0 | G17: 0 | H17: =((YEAR(TODAY())-YEAR(M17))*12+MONTH(TODAY())-MONTH(M17))/12 -> 1.4166667 | I17: 7495077144 | J17: Ghisan Al Azhali | L17: Sales Electric Staff Soekarno Hatta | M17: 45628 | N17: Islam | O17: 33840 | Q17: =IF(COUNTIF('JAN26'!$G:$G, D17)=0, "Tidak Ada", "Ada") -> Ada
A18: ST | B18: NO | C18: 4 | D18: PMD2512005 | E18: 0 | F18: 0 | G18: 1 | H18: =((YEAR(TODAY())-YEAR(M18))*12+MONTH(TODAY())-MONTH(M18))/12 -> 0.41666667 | I18: 1390637132 | J18: Virsqi Indra Perdana | L18: Sales Electric Staff Soekarno Hatta | M18: 46000 | N18: Islam | O18: 34636 | Q18: =IF(COUNTIF('JAN26'!$G:$G, D18)=0, "Tidak Ada", "Ada") -> Ada
A19: ST | B19: NO | C19: 5 | D19: PMD2512008 | E19: 0 | F19: 5 | G19: 0 | H19: =((YEAR(TODAY())-YEAR(M19))*12+MONTH(TODAY())-MONTH(M19))/12 -> 0.41666667 | I19: 3741721129 | J19: Renaldi Agustiana Yusuf | L19: Sales Electric Staff Soekarno Hatta | M19: 46006 | N19: Islam | O19: 36032 | Q19: =IF(COUNTIF('JAN26'!$G:$G, D19)=0, "Tidak Ada", "Ada") -> Ada
A20: ST | B20: NO | C20: 1 | D20: PMD2012002 | E20: 0 | F20: 0 | G20: 0 | H20: =((YEAR(TODAY())-YEAR(M20))*12+MONTH(TODAY())-MONTH(M20))/12 -> 5.4166667 | I20: 0631281850 | J20: Aston Villa | K20: 46125 | L20: Sales Coordinator Pipe & Pump Division Soekarno Hatta | M20: 44172 | N20: Islam | O20: 31221 | P20: HOLD | Q20: =IF(COUNTIF('JAN26'!$G:$G, D20)=0, "Tidak Ada", "Ada") -> Ada
A21: ST | B21: NO | C21: 2 | D21: PMD2402001 | E21: 0 | F21: 0 | G21: 0 | H21: =((YEAR(TODAY())-YEAR(M21))*12+MONTH(TODAY())-MONTH(M21))/12 -> 2.25 | I21: 8103039361 | J21: Agus Gunawan | L21: Sales Pipe & Pump Staff Soekarno Hatta | M21: 45334 | N21: Islam | O21: 32768 | Q21: =IF(COUNTIF('JAN26'!$G:$G, D21)=0, "Tidak Ada", "Ada") -> Ada
A22: ST | B22: NO | C22: 3 | D22: PMD2407002 | E22: 0 | F22: 0 | G22: 2 | H22: =((YEAR(TODAY())-YEAR(M22))*12+MONTH(TODAY())-MONTH(M22))/12 -> 1.8333333 | I22: 1760287934 | J22: Andre Setiawan | L22: Sales Pipe & Pump Staff Soekarno Hatta | M22: 45481 | N22: Islam | O22: 35959 | Q22: =IF(COUNTIF('JAN26'!$G:$G, D22)=0, "Tidak Ada", "Ada") -> Ada
A23: ST | B23: NO | C23: 4 | D23: PMD2502005 | E23: 0 | F23: 0 | G23: 0 | H23: =((YEAR(TODAY())-YEAR(M23))*12+MONTH(TODAY())-MONTH(M23))/12 -> 1.25 | I23: 2801445111 | J23: Erlan Sopiana | L23: Sales Pipe & Pump Staff Soekarno Hatta | M23: 45713 | N23: Islam | O23: 35233 | Q23: =IF(COUNTIF('JAN26'!$G:$G, D23)=0, "Tidak Ada", "Ada") -> Ada
A24: ST | B24: NO | C24: 5 | D24: PMD2506001 | E24: 0 | F24: 0 | G24: 0 | H24: =((YEAR(TODAY())-YEAR(M24))*12+MONTH(TODAY())-MONTH(M24))/12 -> 0.91666667 | I24: 8106058160 | J24: Hendikus Waruwu | K24: 46111 | L24: Sales Pipe & Pump Staff Soekarno Hatta | M24: 45838 | N24: Katolik | O24: 37450 | Q24: =IF(COUNTIF('JAN26'!$G:$G, D24)=0, "Tidak Ada", "Ada") -> Ada
A25: ST | B25: NO | C25: 6 | D25: PMD2107003 | E25: 0 | F25: 0 | G25: 0 | H25: =((YEAR(TODAY())-YEAR(M25))*12+MONTH(TODAY())-MONTH(M25))/12 -> 4.8333333 | I25: 2830811802 | J25: Yus Yusuf Angga Setiabudi | L25: Sales Pipe & Pump Staff Soekarno Hatta | M25: 44403 | N25: Islam | O25: 32155 | Q25: =IF(COUNTIF('JAN26'!$G:$G, D25)=0, "Tidak Ada", "Ada") -> Ada
A26: ST | B26: NO | C26: 8 | D26: PMD2511002 | E26: 0 | F26: 0 | G26: 0 | H26: =((YEAR(TODAY())-YEAR(M26))*12+MONTH(TODAY())-MONTH(M26))/12 -> 0.5 | I26: 2831900280 | J26: Tegoeh Pramono | L26: Sales Pipe & Pump Staff Soekarno Hatta | M26: 45978 | N26: Islam | O26: 31614 | Q26: =IF(COUNTIF('JAN26'!$G:$G, D26)=0, "Tidak Ada", "Ada") -> Ada
A27: ST | B27: NO | C27: 9 | D27: PMD2511004 | E27: 0 | F27: 0 | G27: 0 | H27: =((YEAR(TODAY())-YEAR(M27))*12+MONTH(TODAY())-MONTH(M27))/12 -> 0.5 | I27: 1392396947 | J27: Leo Ferdiansyah | L27: Sales Pipe & Pump Staff Soekarno Hatta | M27: 45979 | N27: Islam | O27: 31274 | Q27: =IF(COUNTIF('JAN26'!$G:$G, D27)=0, "Tidak Ada", "Ada") -> Ada
A28: ST | B28: NO | C28: 1 | D28: PMD2111013 | E28: 0 | F28: 0 | G28: 0 | H28: =((YEAR(TODAY())-YEAR(M28))*12+MONTH(TODAY())-MONTH(M28))/12 -> 4.5 | I28: 2830825579 | J28: Rahmat Hidayat | L28: Sales Paint Staff Soekarno Hatta | M28: 44525 | N28: Islam | O28: 27249 | Q28: =IF(COUNTIF('JAN26'!$G:$G, D28)=0, "Tidak Ada", "Ada") -> Ada
A29: ST | B29: NO | C29: 2 | D29: PMD2201006 | E29: 0 | F29: 0 | G29: 0 | H29: =((YEAR(TODAY())-YEAR(M29))*12+MONTH(TODAY())-MONTH(M29))/12 -> 4.3333333 | I29: 1393356867 | J29: Dadan Hardiansah Putra | K29: 46055 | L29: Sales Paint Staff Soekarno Hatta | M29: 44572 | N29: Islam | O29: 29884 | Q29: =IF(COUNTIF('JAN26'!$G:$G, D29)=0, "Tidak Ada", "Ada") -> Ada
A30: ST | B30: NO | C30: 3 | D30: PMD2112004 | E30: 0 | F30: 0 | G30: 0 | H30: =((YEAR(TODAY())-YEAR(M30))*12+MONTH(TODAY())-MONTH(M30))/12 -> 4.4166667 | I30: 1393317101 | J30: Moch Armando Vebby | L30: Sales Supervisor Paint Staff Soekarno Hatta | M30: 44533 | N30: Islam | O30: 32685 | Q30: =IF(COUNTIF('JAN26'!$G:$G, D30)=0, "Tidak Ada", "Ada") -> Ada
A31: ST | B31: NO | C31: 4 | D31: PMD2201008 | E31: 0 | F31: 0 | G31: 0 | H31: =((YEAR(TODAY())-YEAR(M31))*12+MONTH(TODAY())-MONTH(M31))/12 -> 4.3333333 | I31: 1760203960 | J31: Andi Kurniawan | L31: Sales Paint Staff Soekarno Hatta | M31: 44572 | N31: Islam | O31: 32726 | Q31: =IF(COUNTIF('JAN26'!$G:$G, D31)=0, "Tidak Ada", "Ada") -> Ada
A32: ST | B32: NO | C32: 5 | D32: PMD2206002 | E32: 0 | F32: 0 | G32: 0 | H32: =((YEAR(TODAY())-YEAR(M32))*12+MONTH(TODAY())-MONTH(M32))/12 -> 3.9166667 | I32: 4372932876 | J32: Satria Pamungkas | L32: Sales Coordinator Paint Division | M32: 44732 | N32: Islam | O32: 29884 | Q32: =IF(COUNTIF('JAN26'!$G:$G, D32)=0, "Tidak Ada", "Ada") -> Ada
A33: ST | B33: NO | C33: 6 | D33: PMD2308002 | E33: 0 | F33: 0 | G33: 0 | H33: =((YEAR(TODAY())-YEAR(M33))*12+MONTH(TODAY())-MONTH(M33))/12 -> 2.75 | I33: 2832258475 | J33: Ikhwan Fiddin | K33: 46136 | L33: Sales Paint Staff Soekarno Hatta | M33: 45139 | N33: Islam | O33: 33909 | P33: HOLD | Q33: =IF(COUNTIF('JAN26'!$G:$G, D33)=0, "Tidak Ada", "Ada") -> Ada
A34: ST | B34: NO | C34: 1 | D34: PMD2201011 | E34: 0 | F34: 0 | G34: 0 | H34: =((YEAR(TODAY())-YEAR(M34))*12+MONTH(TODAY())-MONTH(M34))/12 -> 4.3333333 | I34: 4371314568 | J34: Ridwan Fauzan Firdaus | L34: Sales Electric Staff Soekarno Hatta | M34: 44588 | N34: Islam | O34: 34627 | Q34: =IF(COUNTIF('JAN26'!$G:$G, D34)=0, "Tidak Ada", "Ada") -> Ada
A35: ST | B35: NO | C35: 2 | D35: PMD2205006 | E35: 0 | F35: 0 | G35: 0 | H35: =((YEAR(TODAY())-YEAR(M35))*12+MONTH(TODAY())-MONTH(M35))/12 -> 4 | I35: 8100893330 | J35: Nur Ali | L35: Sales Coordinator Electric Soekarno Hatta | M35: 44706 | N35: Islam | O35: 35135 | Q35: =IF(COUNTIF('JAN26'!$G:$G, D35)=0, "Tidak Ada", "Ada") -> Ada
A36: ST | B36: NO | C36: 1 | D36: PMB2506001 | E36: 0 | F36: 0 | G36: 0 | H36: =((YEAR(TODAY())-YEAR(M36))*12+MONTH(TODAY())-MONTH(M36))/12 -> 0.91666667 | I36: 7380496873 | J36: Ramli Nasution | K36: 46146 | L36: Sales ICI Coordinator Bogor | M36: 45817 | N36: Islam | O36: 30054 | P36: HOLD | Q36: =IF(COUNTIF('JAN26'!$G:$G, D36)=0, "Tidak Ada", "Ada") -> Ada
A37: ST | B37: NO | C37: 2 | D37: PMB1909012 | E37: 0 | F37: 0 | G37: 0 | H37: =((YEAR(TODAY())-YEAR(M37))*12+MONTH(TODAY())-MONTH(M37))/12 -> 6.6666667 | I37: 3370017751 | J37: Lucky Gema Christyan Syah | L37: Sales ICI Staff Bogor | M37: 43731 | N37: Islam | O37: 33253 | Q37: =IF(COUNTIF('JAN26'!$G:$G, D37)=0, "Tidak Ada", "Ada") -> Ada
A38: ST | B38: NO | C38: 3 | D38: PMB2105004 | E38: 1 | F38: 0 | G38: 0 | H38: =((YEAR(TODAY())-YEAR(M38))*12+MONTH(TODAY())-MONTH(M38))/12 -> 5 | I38: 8720710197 | J38: Zaenudin | L38: Sales ICI Staff Bogor | M38: 44341 | N38: Islam | O38: 32708 | Q38: =IF(COUNTIF('JAN26'!$G:$G, D38)=0, "Tidak Ada", "Ada") -> Ada
A39: ST | B39: NO | C39: 4 | D39: PMB2405006 | E39: 1 | F39: 0 | G39: 0 | H39: =((YEAR(TODAY())-YEAR(M39))*12+MONTH(TODAY())-MONTH(M39))/12 -> 2 | I39: 0953412346 | J39: Asep Permana Noor | L39: Sales ICI Staff Bogor | M39: 45426 | N39: Islam | O39: 31565 | Q39: =IF(COUNTIF('JAN26'!$G:$G, D39)=0, "Tidak Ada", "Ada") -> Ada
A40: ST | B40: NO | C40: 5 | D40: PMB2411002 | E40: 1 | F40: 0 | G40: 0 | H40: =((YEAR(TODAY())-YEAR(M40))*12+MONTH(TODAY())-MONTH(M40))/12 -> 1.5 | I40: 1672882235 | J40: Fajar Nugraha | L40: Sales ICI Staff Bogor | M40: 45616 | N40: Islam | O40: 34033 | Q40: =IF(COUNTIF('JAN26'!$G:$G, D40)=0, "Tidak Ada", "Ada") -> Ada
...

Sheet Sheet5
A1: Data HR yang tidak ada di Data Bu Gita
A3: St | B3: FIX | C3: Nu | D3: NIK | E3: Sakit | F3: Izin | G3: Alpha | H3: Lama Kerja | I3: No AC | J3: Dept and Location | K3: Tgl Resign | L3: Posisi | M3: Tgl Masuk | N3: Agama | O3: Tgl Lahir | P3: Keterangan
A4: ST | B4: NO | C4: 1 | D4: PMD2207003 | E4: 0 | F4: 0 | G4: 0 | H4: 2.75 | I4: 1560107931 | J4: Ricki Galih Ginanjar | L4: Coordinator Sales Pipamas Division | M4: 45169 | N4: Islam | O4: 32129
A5: ST | B5: NO | C5: 7 | D5: PMD2601002 | E5: 0 | F5: 0 | G5: 0 | H5: 0.33333333 | I5: 6610706418 | J5: Fitrah Ramadhan | L5: Sales ICI Staff Bogor | M5: 46051 | N5: Islam | O5: 35117
A6: ST | B6: NO | C6: 1 | D6: PMC2204005 | E6: 0 | F6: 0 | G6: 0 | H6: 4.0833333 | I6: 8180379941 | J6: Ismanto | L6: Sales Electric, Pipamas, Pipe & Pump Supervisor Cirebon | M6: 44669 | N6: Islam | O6: 28678
A7: ST | B7: NO | C7: 3 | D7: PMC2203003 | E7: 0 | F7: 0 | G7: 0 | H7: 4.1666667 | I7: 8180374729 | J7: Moch Apip | L7: Coordinator Sales Electric Cirebon | M7: 44645 | N7: Islam | O7: 33527
A8: ST | B8: NO | C8: 1 | D8: PMC2007006 | E8: 0 | F8: 0 | G8: 0 | H8: 5.8333333 | I8: 4380053131 | J8: Rastha Kawistara | L8: Coordinator Sales Pipamas Cirebon | M8: 44034 | N8: Islam | O8: 32802
A9: ST | B9: NO | C9: 1 | D9: PMC2209001 | E9: 0 | F9: 0 | G9: 0 | H9: 3.6666667 | I9: 3740904263 | J9: Aldy Sulistio | L9: Coordinator Sales Pipe & Pump Cirebon | M9: 44816 | N9: Islam | O9: 35010
A10: ST | B10: NO | C10: 2 | D10: PMT2209001 | E10: 0 | F10: 0 | G10: 0 | H10: 3.6666667 | I10: 0541950825 | J10: Ar Ar Satia Rahmat | L10: Sales Pipamas Coordinator Tasikmalaya | M10: 44816 | N10: Islam | O10: 30884
A11: ST | B11: NO | C11: 1 | D11: PMT1910005 | E11: 0 | F11: 0 | G11: 0 | H11: 6.5833333 | I11: 0540741735 | J11: Rikza Maulana | L11: Sales Coordinator Electric Division Tasikmalaya | M11: 43740 | N11: Islam | O11: 30524
A12: ST | B12: NO | C12: 1 | D12: PMT1907023 | E12: 0 | F12: 0 | G12: 0 | H12: 6.8333333 | I12: 0540714282 | J12: Asep Mamat Harisudin | L12: Coordinator Sales Pipe & Pump Tasikmalaya | M12: 43675 | N12: Islam | O12: 29170
A13: ST | B13: NO | C13: 1 | D13: PMT1910006 | E13: 0 | F13: 0 | G13: 0 | H13: 6.5833333 | I13: 2090538252 | J13: Ade Hendra | L13: Sales ICI Coordinator Tasikmalaya | M13: 43740 | N13: Islam | O13: 32176

Sheet Sheet6
A1: Kode Sales | B1: Divisi | C1: Jabatan | D1: Column1 | E1: ket
A2: SPVPP01 | B2: PP | C2: Spv PP Bandung | D2: PA MARTIN
A3: SPVEL01 | B3: EL | C3: Spv EL Bandung | D3: PA MARTIN
A4: PPCOS01 | B4: PP | C4: Cosales PP Bandung | D4: GERY ISKANDAR
A5: PISPV01 | B5: PI | C5: Spv PI Bandung | D5: KOSONG
A6: PICOS08 | B6: PI | C6: Cosales PI Bogor | D6: KOSONG
A7: ICSLM08 | B7: ICI | C7: Spv IC Bandung | D7: PAK ARMANDO
A8: ICCOS08 | B8: ICI | C8: Cosales IC Bogor | D8: PAK RAMLI | E8: Februari ganti kode jadi ICCOS08
A9: ELSPV08 | B9: EL | C9: Spv EL Bogor | D9: NANDA AMELIA

Sheet JAN26
A1: Branch | B1: Divisi | C1: Kode Sales | D1: Januari | E1: Masuk | F1: Keluar | G1: NIK | H1: No Rek | I1: Data HR | J1: Status
A2: Bandung | B2: Elektrik | C2: ELMOD01 | D2: Ridwan Fauzan Firdaus | E2: 44588 | G2: PMD2201011 | H2: 4371314568 | I2: =IFERROR(VLOOKUP(G2,'20an'!$D:$J,7,0), "Sales tidak ada di data HR") -> Ridwan Fauzan Firdaus | J2: =I2='JAN26'!$D2 -> TRUE
A3: Bandung | B3: Elektrik | C3: ELMOD02 | D3: Nur Ali | E3: 44706 | G3: PMD2205006 | H3: 8100893330 | I3: =IFERROR(VLOOKUP(G3,'20an'!$D:$J,7,0), "Sales tidak ada di data HR") -> Nur Ali | J3: =I3='JAN26'!$D3 -> TRUE | L3: ICSLM08
A4: Bandung | B4: Elektrik | C4: ELSLE01 | D4: RENALDI AGUSTIANA YUSUF | E4: 46006 | G4: PMD2512008 | H4: 3741721129 | I4: =IFERROR(VLOOKUP(G4,'20an'!$D:$J,7,0), "Sales tidak ada di data HR") -> Renaldi Agustiana Yusuf | J4: =I4='JAN26'!$D4 -> TRUE | L4: PISPV01
A5: Bandung | B5: Elektrik | C5: ELSLE02 | D5: Syamsul Palah | E5: 45533 | G5: PMD2408006 | H5: 7940315390 | I5: =IFERROR(VLOOKUP(G5,'20an'!$D:$J,7,0), "Sales tidak ada di data HR") -> Syamsul Palah | J5: =I5='JAN26'!$D5 -> TRUE | L5: SPVEL01
A6: Bandung | B6: Elektrik | C6: ELSLE03 | D6: Ghisan Al Azhali | E6: 45628 | G6: PMD2412001 | H6: 7495077144 | I6: =IFERROR(VLOOKUP(G6,'20an'!$D:$J,7,0), "Sales tidak ada di data HR") -> Ghisan Al Azhali | J6: =I6='JAN26'!$D6 -> TRUE | L6: ICCOS08
A7: Bandung | B7: Elektrik | C7: ELSLE04 | D7: Virsqi Indra Perdana | E7: 46000 | G7: PMD2512005 | H7: 1390637132 | I7: =IFERROR(VLOOKUP(G7,'20an'!$D:$J,7,0), "Sales tidak ada di data HR") -> Virsqi Indra Perdana | J7: =I7='JAN26'!$D7 -> TRUE | L7: PICOS08
A8: Bandung | B8: Elektrik | C8: ELSLE05 | D8: Hasudungan | E8: 44704 | G8: PMD2205003 | H8: 2810384045 | I8: =IFERROR(VLOOKUP(G8,'20an'!$D:$J,7,0), "Sales tidak ada di data HR") -> Hasudungan | J8: =I8='JAN26'!$D8 -> TRUE | L8: PPCOS01
A9: Bandung | B9: Elektrik | C9: ELCOS01 | D9: ROSADI | E9: 45908 | F9: 46031 | G9: PMD2509004 | H9: 5170024461 | I9: =IFERROR(VLOOKUP(G9,'20an'!$D:$J,7,0), "Sales tidak ada di data HR") -> Sales tidak ada di data HR | J9: =I9='JAN26'!$D9 -> FALSE | L9: SPVPP01
A10: PCK | B10: Elektrik | C10: ELSLE25 | D10: Kiki Hadisurya | E10: 45649 | G10: PMK2412001 | H10: 87042531 | I10: =IFERROR(VLOOKUP(G10,'20an'!$D:$J,7,0), "Sales tidak ada di data HR") -> Kiki Hadisurya | J10: =I10='JAN26'!$D10 -> TRUE | L10: ELSPV08
A11: Cirebon | B11: Elektrik | C11: ELSLE60 | D11: Nurfadilah | E11: 44951 | G11: PMC2301001 | H11: 1342293292 | I11: =IFERROR(VLOOKUP(G11,'20an'!$D:$J,7,0), "Sales tidak ada di data HR") -> Nurfadilah | J11: =I11='JAN26'!$D11 -> TRUE
A12: Cirebon | B12: Elektrik | C12: ELSLE61 | D12: Fanji Berliandy Azhari Ridzki | E12: 44536 | G12: PMC2112006 | H12: 8180224085 | I12: =IFERROR(VLOOKUP(G12,'20an'!$D:$J,7,0), "Sales tidak ada di data HR") -> Fanji Berliandy Azhari Ridzki | J12: =I12='JAN26'!$D12 -> TRUE
A13: Cirebon | B13: Elektrik | C13: ELSLE62 | D13: Ade Trihandoyo | E13: 45845 | G13: PMC2507002 | H13: 373802651 | I13: =IFERROR(VLOOKUP(G13,'20an'!$D:$J,7,0), "Sales tidak ada di data HR") -> Ade Trihandoyo | J13: =I13='JAN26'!$D13 -> TRUE
A14: Cirebon | B14: Elektrik | C14: ELSLE63 | D14: Fidyah Faroid | E14: 45502 | G14: PMC2407004 | H14: 8180505475 | I14: =IFERROR(VLOOKUP(G14,'20an'!$D:$J,7,0), "Sales tidak ada di data HR") -> Fidyah Faroid | J14: =I14='JAN26'!$D14 -> TRUE
A15: Cirebon | B15: Elektrik | C15: ELSLE64 | D15: Eko Yoga Prawira | E15: 45708 | G15: PMC2502002 | H15: 1342833637 | I15: =IFERROR(VLOOKUP(G15,'20an'!$D:$J,7,0), "Sales tidak ada di data HR") -> Eko Yoga Prawira | J15: =I15='JAN26'!$D15 -> TRUE
A16: Cirebon | B16: Elektrik | C16: ELSLE65 | D16: Ipan Wiguna | E16: 45643 | G16: PMC2412003 | H16: 2991983084 | I16: =IFERROR(VLOOKUP(G16,'20an'!$D:$J,7,0), "Sales tidak ada di data HR") -> Ipan Wiguna | J16: =I16='JAN26'!$D16 -> TRUE
A17: Tasik | B17: Elektrik | C17: ELSLE71 | D17: Firmansyah | E17: 45468 | G17: PMT2406003 | H17: 3211177428 | I17: =IFERROR(VLOOKUP(G17,'20an'!$D:$J,7,0), "Sales tidak ada di data HR") -> Firmansyah | J17: =I17='JAN26'!$D17 -> TRUE
A18: Tasik | B18: Elektrik | C18: ELSLE72 | D18: Dhia Ul Iman | E18: 44734 | G18: PMT2206001 | H18: 3210914411 | I18: =IFERROR(VLOOKUP(G18,'20an'!$D:$J,7,0), "Sales tidak ada di data HR") -> Dhia Ul Iman | J18: =I18='JAN26'!$D18 -> TRUE
A19: Tasik | B19: Elektrik | C19: ELSLE73 | D19: Veby Rizky Fauzi | E19: 45558 | G19: PMT2409001 | H19: 541384501 | I19: =IFERROR(VLOOKUP(G19,'20an'!$D:$J,7,0), "Sales tidak ada di data HR") -> Veby Rizky Fauzi | J19: =I19='JAN26'!$D19 -> TRUE
A20: Tasik | B20: Elektrik | C20: ELSLE74 | D20: Dian Haerandi | E20: 45820 | G20: PMT2506001 | H20: 3211265807 | I20: =IFERROR(VLOOKUP(G20,'20an'!$D:$J,7,0), "Sales tidak ada di data HR") -> Dian Haerandi | J20: =I20='JAN26'!$D20 -> TRUE
A21: Tasik | B21: Elektrik | C21: ELSLE75 | D21: Jejen Al Kohiri | E21: 45679 | G21: PMT2501001 | H21: 3210680810 | I21: =IFERROR(VLOOKUP(G21,'20an'!$D:$J,7,0), "Sales tidak ada di data HR") -> Jejen Al Kohiri | J21: =I21='JAN26'!$D21 -> TRUE
A22: Bogor | B22: Elektrik | C22: ELSLE85 | D22: Syahri Rizki | E22: 45414 | G22: PMB2405003 | H22: 3720066482 | I22: =IFERROR(VLOOKUP(G22,'20an'!$D:$J,7,0), "Sales tidak ada di data HR") -> Syahri Rizki | J22: =I22='JAN26'!$D22 -> TRUE
... A34: PCK | B34: ICI | C34: ICSLM23 | D34: Bonar Jumada | E34: 43349 | G34: PMK1809003 | H34: 5770551341 | I34: =IFERROR(VLOOKUP(G34,'20an'!$D:$J,7,0), "Sales tidak ada di data HR") -> Bonar Jumada | J34: =I34='JAN26'!$D34 -> TRUE
A35: PCK | B35: ICI | C35: ICSLM28 | D35: Adhi Gustiana | E35: 43332 | G35: PMK1808008 | H35: 2310272283 | I35: =IFERROR(VLOOKUP(G35,'20an'!$D:$J,7,0), "Sales tidak ada di data HR") -> Sales tidak ada di data HR | J35: =I35='JAN26'!$D35 -> FALSE | K35: Aktif
A36: Tasik | B36: ICI | C36: ICSLM71 | D36: Faizal Abdul Jabbar | E36: 44533 | G36: PMT2112005 | H36: 3210847285 | I36: =IFERROR(VLOOKUP(G36,'20an'!$D:$J,7,0), "Sales tidak ada di data HR") -> Faizal Abdul Jabbar | J36: =I36='JAN26'!$D36 -> TRUE
A37: Tasik | B37: ICI | C37: ICSLM72 | D37: Septian Hermansyah | E37: 44781 | G37: PMT2208001 | H37: 3210939872 | I37: =IFERROR(VLOOKUP(G37,'20an'!$D:$J,7,0), "Sales tidak ada di data HR") -> Septian Hermansyah | J37: =I37='JAN26'!$D37 -> TRUE
A38: Tasik | B38: ICI | C38: ICSLM73 | D38: Nandang Tata Yusmana | E38: 45824 | G38: PMT2506002 | H38: 541621678 | I38: =IFERROR(VLOOKUP(G38,'20an'!$D:$J,7,0), "Sales tidak ada di data HR") -> Nandang Tata Yusmana | J38: =I38='JAN26'!$D38 -> TRUE
A39: Bogor | B39: ICI | C39: ICSLM80 | D39: Ramli Nasution | E39: 45817 | G39: PMB2506001 | H39: 7380496873 | I39: =IFERROR(VLOOKUP(G39,'20an'!$D:$J,7,0), "Sales tidak ada di data HR") -> Ramli Nasution | J39: =I39='JAN26'!$D39 -> TRUE
A40: Bogor | B40: ICI | C40: ICSLM81 | D40: Asep Permana Noor | E40: 45426 | G40: PMB2405006 | H40: 953412346 | I40: =IFERROR(VLOOKUP(G40,'20an'!$D:$J,7,0), "Sales tidak ada di data HR") -> Asep Permana Noor | J40: =I40='JAN26'!$D40 -> TRUE
A41: Bogor | B41: ICI | C41: ICSLM82 | D41: Fajar Nugraha | E41: 45616 | G41: PMB2411002 | H41: 1672882235 | I41: =IFERROR(VLOOKUP(G41,'20an'!$D:$J,7,0), "Sales tidak ada di data HR") -> Fajar Nugraha | J41: =I41='JAN26'!$D41 -> TRUE
A42: Bogor | B42: ICI | C42: ICSLM83 | D42: Zaenudin | E42: 44341 | G42: PMB2105004 | H42: 8720710197 | I42: =IFERROR(VLOOKUP(G42,'20an'!$D:$J,7,0), "Sales tidak ada di data HR") -> Zaenudin | J42: =I42='JAN26'!$D42 -> TRUE
A43: Bogor | B43: ICI | C43: ICSLM84 | D43: Lucky Gema Christyan Syah | E43: 43731 | G43: PMB1909012 | H43: 3370017751 | I43: =IFERROR(VLOOKUP(G43,'20an'!$D:$J,7,0), "Sales tidak ada di data HR") -> Lucky Gema Christyan Syah | J43: =I43='JAN26'!$D43 -> TRUE
A44: Bogor | B44: ICI | C44: ICSLM85 | D44: Andri Prayitno | E44: 45530 | F44: 46027 | G44: PMB2408001 | H44: 8720384575 | I44: =IFERROR(VLOOKUP(G44,'20an'!$D:$J,7,0), "Sales tidak ada di data HR") -> Sales tidak ada di data HR | J44: =I44='JAN26'!$D44 -> FALSE
A45: Bandung | B45: Pipamas | C45: PISLP01 | D45: ASEP SOPIYAN | E45: 45896 | G45: PMD2508010 | H45: 3790592777 | I45: =IFERROR(VLOOKUP(G45,'20an'!$D:$J,7,0), "Sales tidak ada di data HR") -> Asep Sopiyan | J45: =I45='JAN26'!$D45 -> TRUE
A46: Bandung | B46: Pipamas | C46: PISLP02 | D46: Hari Wiharyana | E46: 45904 | G46: PMD2509003 | H46: 2800939910 | I46: =IFERROR(VLOOKUP(G46,'20an'!$D:$J,7,0), "Sales tidak ada di data HR") -> Hari Wiharyana | J46: =I46='JAN26'!$D46 -> TRUE
A47: Bandung | B47: Pipamas | C47: PISLP03 | D47: Vacant | E47: 0-Jan-1900 | G47: 0 | H47: 0 | I47: =IFERROR(VLOOKUP(G47,'20an'!$D:$J,7,0), "Sales tidak ada di data HR") -> Sales tidak ada di data HR | J47: =I47='JAN26'!$D47 -> FALSE
A48: Bandung | B48: Pipamas | C48: PISLP04 | D48: Gugun Hanafi | E48: 45727 | G48: PMD2503004 | H48: 1560108695 | I48: =IFERROR(VLOOKUP(G48,'20an'!$D:$J,7,0), "Sales tidak ada di data HR") -> Gugun Hanafi | J48: =I48='JAN26'!$D48 -> TRUE
A49: Bandung | B49: Pipamas | C49: PISLP05 | D49: Vacant | E49: 0-Jan-1900 | G49: 0 | H49: 0 | I49: =IFERROR(VLOOKUP(G49,'20an'!$D:$J,7,0), "Sales tidak ada di data HR") -> Sales tidak ada di data HR | J49: =I49='JAN26'!$D49 -> FALSE
A50: Bandung | B50: Pipamas | C50: PISLP06 | D50: Aditya Muhammad Ramdhan | E50: 45727 | G50: PMD2503003 | H50: 7750965185 | I50: =IFERROR(VLOOKUP(G50,'20an'!$D:$J,7,0), "Sales tidak ada di data HR") -> Aditya Muhammad Ramdhan | J50: =I50='JAN26'!$D50 -> TRUE
A51: Bandung | B51: Pipamas | C51: PISLP07 | D51: Bagus Gumilar | E51: 44858 | G51: PMD2210008 | H51: 83879235 | I51: =IFERROR(VLOOKUP(G51,'20an'!$D:$J,7,0), "Sales tidak ada di data HR") -> Bagus Gumilar | J51: =I51='JAN26'!$D51 -> TRUE
...

Sheet Karyawan Resign
A1: St | B1: FIX | C1: Nu | D1: NIK | E1: Sakit | F1: Izin | G1: Alpha | H1: Lama Kerja | I1: No AC | J1: Dept and Location | K1: Tgl Resign | L1: Posisi | M1: Tgl Masuk | N1: Agama | O1: Tgl Lahir | P1: Keterangan
A2: ST | B2: NO | C2: 1 | D2: PMT2012001 | E2: 0 | F2: 0 | G2: 0 | H2: =((YEAR(TODAY())-YEAR(M2))*12+MONTH(TODAY())-MONTH(M2))/12 -> 5.4166667 | I2: 1380425293 | J2: Yendi Cahyadi | K2: 46034 | L2: Sales Pipe & Pump Staff Tasikmalaya | M2: 44172 | N2: Islam | O2: 33757
A3: ST | B3: NO | C3: 2 | D3: PMD2509004 | E3: 0 | F3: 0 | G3: 0 | H3: =((YEAR(TODAY())-YEAR(M3))*12+MONTH(TODAY())-MONTH(M3))/12 -> 0.66666667 | I3: 5170024461 | J3: Rosadi | K3: 46034 | L3: Sales Electric Coordinator Soekarno Hatta | M3: 45908 | N3: Islam | O3: 33122
A4: ST | B4: NO | C4: 3 | D4: PMD2512004 | E4: 0 | F4: 0 | G4: 0 | H4: =((YEAR(TODAY())-YEAR(M4))*12+MONTH(TODAY())-MONTH(M4))/12 -> 0.41666667 | I4: 7771774958 | J4: Pelsa Christian | K4: 46031 | L4: Sales Pipe & Pump Staff Soekarno Hatta | M4: 45999 | N4: Islam | O4: 33239
A5: ST | B5: NO | C5: 4 | D5: PMT2207002 | E5: 0 | F5: 0 | G5: 0 | H5: =((YEAR(TODAY())-YEAR(M5))*12+MONTH(TODAY())-MONTH(M5))/12 -> 3.8333333 | I5: 2090798238 | J5: Dian Nursamsi | K5: 46041 | L5: Sales Pipamas Staff Tasikmalaya | M5: 44771 | N5: Islam | O5: 34092 | P5: HOLD

Sheet Bandung
A1: ELEKTRIK BANDUNG
A3: Branch | B3: Divisi | C3: Kode Sales | D3: Januari | E3: Masuk | F3: Keluar | G3: NIK | H3: No Rek
A4: =IF(LEFT(RIGHT(C4,2),1)="0","Bandung",IF(LEFT(RIGHT(C4,2),1)="2","PCK",IF(LEFT(RIGHT(C4,2),1)="6","Cirebon",IF(LEFT(RIGHT(C4,2),1)="7","Tasik",IF(LEFT(RIGHT(C4,2),1)="8","Bogor",""))))) -> Bandung | B4: =IF(LEFT(C4,2)="EL","Elektrik",IF(LEFT(C4,2)="PP","Pipa Pompa",IF(LEFT(C4,2)="IC","ICI",IF(LEFT(C4,2)="PI","Pipamas","")))) -> Elektrik | C4: ELMOD01 | D4: Ridwan Fauzan Firdaus | E4: =IFERROR(INDEX(#REF!,MATCH([1]!Table79101112[[#This Row],[Januari]],#REF!,0)),"kosong") -> kosong | G4: =IFERROR(INDEX(#REF!,MATCH([1]!Table79101112[[#This Row],[Januari]],#REF!,0)),"") | H4: =IFERROR(INDEX(#REF!,MATCH([1]!Table79101112[[#This Row],[Januari]],#REF!,0)),"")
A5: =IF(LEFT(RIGHT(C5,2),1)="0","Bandung",IF(LEFT(RIGHT(C5,2),1)="2","PCK",IF(LEFT(RIGHT(C5,2),1)="6","Cirebon",IF(LEFT(RIGHT(C5,2),1)="7","Tasik",IF(LEFT(RIGHT(C5,2),1)="8","Bogor",""))))) -> Bandung | B5: =IF(LEFT(C5,2)="EL","Elektrik",IF(LEFT(C5,2)="PP","Pipa Pompa",IF(LEFT(C5,2)="IC","ICI",IF(LEFT(C5,2)="PI","Pipamas","")))) -> Elektrik | C5: ELMOD02 | D5: Nur Ali | E5: =IFERROR(INDEX(#REF!,MATCH([1]!Table79101112[[#This Row],[Januari]],#REF!,0)),"kosong") -> kosong | G5: =IFERROR(INDEX(#REF!,MATCH([1]!Table79101112[[#This Row],[Januari]],#REF!,0)),"") | H5: =IFERROR(INDEX(#REF!,MATCH([1]!Table79101112[[#This Row],[Januari]],#REF!,0)),"")
A6: =IF(LEFT(RIGHT(C6,2),1)="0","Bandung",IF(LEFT(RIGHT(C6,2),1)="2","PCK",IF(LEFT(RIGHT(C6,2),1)="6","Cirebon",IF(LEFT(RIGHT(C6,2),1)="7","Tasik",IF(LEFT(RIGHT(C6,2),1)="8","Bogor",""))))) -> Bandung | B6: =IF(LEFT(C6,2)="EL","Elektrik",IF(LEFT(C6,2)="PP","Pipa Pompa",IF(LEFT(C6,2)="IC","ICI",IF(LEFT(C6,2)="PI","Pipamas","")))) -> Elektrik | C6: ELSLE01 | D6: RENALDI AGUSTIANA YUSUF | E6: =IFERROR(INDEX(#REF!,MATCH([1]!Table79101112[[#This Row],[Januari]],#REF!,0)),"kosong") -> kosong | G6: =IFERROR(INDEX(#REF!,MATCH([1]!Table79101112[[#This Row],[Januari]],#REF!,0)),"") | H6: =IFERROR(INDEX(#REF!,MATCH([1]!Table79101112[[#This Row],[Januari]],#REF!,0)),"") | I6: Pak Martin
A7: =IF(LEFT(RIGHT(C7,2),1)="0","Bandung",IF(LEFT(RIGHT(C7,2),1)="2","PCK",IF(LEFT(RIGHT(C7,2),1)="6","Cirebon",IF(LEFT(RIGHT(C7,2),1)="7","Tasik",IF(LEFT(RIGHT(C7,2),1)="8","Bogor",""))))) -> Bandung | B7: =IF(LEFT(C7,2)="EL","Elektrik",IF(LEFT(C7,2)="PP","Pipa Pompa",IF(LEFT(C7,2)="IC","ICI",IF(LEFT(C7,2)="PI","Pipamas","")))) -> Elektrik | C7: ELSLE02 | D7: Syamsul Palah | E7: =IFERROR(INDEX(#REF!,MATCH([1]!Table79101112[[#This Row],[Januari]],#REF!,0)),"kosong") -> kosong | G7: =IFERROR(INDEX(#REF!,MATCH([1]!Table79101112[[#This Row],[Januari]],#REF!,0)),"") | H7: =IFERROR(INDEX(#REF!,MATCH([1]!Table79101112[[#This Row],[Januari]],#REF!,0)),"")
A8: =IF(LEFT(RIGHT(C8,2),1)="0","Bandung",IF(LEFT(RIGHT(C8,2),1)="2","PCK",IF(LEFT(RIGHT(C8,2),1)="6","Cirebon",IF(LEFT(RIGHT(C8,2),1)="7","Tasik",IF(LEFT(RIGHT(C8,2),1)="8","Bogor",""))))) -> Bandung | B8: =IF(LEFT(C8,2)="EL","Elektrik",IF(LEFT(C8,2)="PP","Pipa Pompa",IF(LEFT(C8,2)="IC","ICI",IF(LEFT(C8,2)="PI","Pipamas","")))) -> Elektrik | C8: ELSLE03 | D8: Ghisan Al Azhali | E8: =IFERROR(INDEX(#REF!,MATCH([1]!Table79101112[[#This Row],[Januari]],#REF!,0)),"kosong") -> kosong | G8: =IFERROR(INDEX(#REF!,MATCH([1]!Table79101112[[#This Row],[Januari]],#REF!,0)),"") | H8: =IFERROR(INDEX(#REF!,MATCH([1]!Table79101112[[#This Row],[Januari]],#REF!,0)),"")
A9: =IF(LEFT(RIGHT(C9,2),1)="0","Bandung",IF(LEFT(RIGHT(C9,2),1)="2","PCK",IF(LEFT(RIGHT(C9,2),1)="6","Cirebon",IF(LEFT(RIGHT(C9,2),1)="7","Tasik",IF(LEFT(RIGHT(C9,2),1)="8","Bogor",""))))) -> Bandung | B9: =IF(LEFT(C9,2)="EL","Elektrik",IF(LEFT(C9,2)="PP","Pipa Pompa",IF(LEFT(C9,2)="IC","ICI",IF(LEFT(C9,2)="PI","Pipamas","")))) -> Elektrik | C9: ELSLE04 | D9: VIRSQI INDRA | E9: =IFERROR(INDEX(#REF!,MATCH([1]!Table79101112[[#This Row],[Januari]],#REF!,0)),"kosong") -> kosong | G9: =IFERROR(INDEX(#REF!,MATCH([1]!Table79101112[[#This Row],[Januari]],#REF!,0)),"") | H9: =IFERROR(INDEX(#REF!,MATCH([1]!Table79101112[[#This Row],[Januari]],#REF!,0)),"")
A10: =IF(LEFT(RIGHT(C10,2),1)="0","Bandung",IF(LEFT(RIGHT(C10,2),1)="2","PCK",IF(LEFT(RIGHT(C10,2),1)="6","Cirebon",IF(LEFT(RIGHT(C10,2),1)="7","Tasik",IF(LEFT(RIGHT(C10,2),1)="8","Bogor",""))))) -> Bandung | B10: =IF(LEFT(C10,2)="EL","Elektrik",IF(LEFT(C10,2)="PP","Pipa Pompa",IF(LEFT(C10,2)="IC","ICI",IF(LEFT(C10,2)="PI","Pipamas","")))) -> Elektrik | C10: ELSLE05 | D10: Hasudungan | E10: =IFERROR(INDEX(#REF!,MATCH([1]!Table79101112[[#This Row],[Januari]],#REF!,0)),"kosong") -> kosong | G10: =IFERROR(INDEX(#REF!,MATCH([1]!Table79101112[[#This Row],[Januari]],#REF!,0)),"") | H10: =IFERROR(INDEX(#REF!,MATCH([1]!Table79101112[[#This Row],[Januari]],#REF!,0)),"")
A11: =IF(LEFT(RIGHT(C11,2),1)="0","Bandung",IF(LEFT(RIGHT(C11,2),1)="2","PCK",IF(LEFT(RIGHT(C11,2),1)="6","Cirebon",IF(LEFT(RIGHT(C11,2),1)="7","Tasik",IF(LEFT(RIGHT(C11,2),1)="8","Bogor",""))))) -> Bandung | B11: =IF(LEFT(C11,2)="EL","Elektrik",IF(LEFT(C11,2)="PP","Pipa Pompa",IF(LEFT(C11,2)="IC","ICI",IF(LEFT(C11,2)="PI","Pipamas","")))) -> Elektrik | C11: ELCOS01 | D11: ROSADI | E11: =IFERROR(INDEX(#REF!,MATCH([1]!Table79101112[[#This Row],[Januari]],#REF!,0)),"kosong") -> kosong | F11: 46031 | G11: =IFERROR(INDEX(#REF!,MATCH([1]!Table79101112[[#This Row],[Januari]],#REF!,0)),"") | H11: =IFERROR(INDEX(#REF!,MATCH([1]!Table79101112[[#This Row],[Januari]],#REF!,0)),"")
A13: ICI BANDUNG
A15: Branch | B15: Divisi | C15: Kode Sales | D15: Januari | E15: Masuk | F15: Keluar | G15: NIK | H15: No Rek
A16: Bandung | B16: ICI | C16: ICSLM01 | D16: Ikhwan Fiddin | E16: 45139 | G16: PMD2308002 | H16: 2832258475
A17: Bandung | B17: ICI | C17: ICSLM03 | D17: Dadan Hardiansah Putra | E17: 44572 | G17: PMD2201006 | H17: 1393356867
A18: Bandung | B18: ICI | C18: ICSLM05 | D18: Moch Armando Vebby | E18: 44533 | G18: PMD2112004 | H18: 1393317101 | I18: Pak Nando
A19: Bandung | B19: ICI | C19: ICSLM06 | D19: Rahmat Hidayat | E19: 44525 | G19: PMD2111013 | H19: 2830825579
A20: Bandung | B20: ICI | C20: ICSLM07 | D20: Satria Pamungkas | E20: 44732 | G20: PMD2206002 | H20: 4372932876
A21: Bandung | B21: ICI | C21: ICSLM09 | D21: Andi Kurniawan | E21: 44572 | G21: PMD2201008 | H21: 1760203960
A23: PP BANDUNG
A25: Branch | B25: Divisi | C25: Kode Sales | D25: Januari | E25: Masuk | F25: Keluar | G25: NIK | H25: No Rek
A26: Bandung | B26: Pipa Pompa | C26: PPSLM01 | D26: Agus Gunawan | E26: 45334 | G26: PMD2402001 | H26: 8103039361
A27: Bandung | B27: Pipa Pompa | C27: PPSLM02 | D27: TEGOEH PRAMONO | E27: 45978 | G27: PMD2511002 | H27: 2831900280
A28: Bandung | B28: Pipa Pompa | C28: PPSLM03 | D28: PELSA CHRISTIAN | E28: 45999 | F28: 46031 | G28: PMD2512004 | H28: 7771774958
A29: Bandung | B29: Pipa Pompa | C29: PPSLM04 | D29: Andre Setiawan | E29: 45481 | G29: PMD2407002 | H29: 1760287934 | I29: Pak Martin
A30: Bandung | B30: Pipa Pompa | C30: PPSLM05 | D30: Yusuf Angga Setiabudi | E30: 45894 | G30: PMD2107003 | H30: 2830811802
A31: Bandung | B31: Pipa Pompa | C31: PPSLM06 | D31: Erlan Sopiana | E31: 45713 | G31: PMD2502005 | H31: 2801445111
A32: Bandung | B32: Pipa Pompa | C32: PPSLM07 | D32: LEO FERDIANSYAH | E32: 45979 | G32: PMD2511004 | H32: 1392396947
A33: Bandung | B33: Pipa Pompa | C33: PPSLM08 | D33: Hendikus Waruwu | E33: 45838 | G33: PMD2506001 | H33: 8106058160
A34: Bandung | B34: Pipa Pompa | C34: PPSLM09 | D34: Vacant | E34: 0 | G34: 0 | H34: 0
A36: PI BANDUNG
A38: Branch | B38: Divisi | C38: Kode Sales | D38: Januari | E38: Masuk | F38: Keluar | G38: NIK | H38: No Rek
A39: Bandung | B39: Pipamas | C39: PISLP01 | D39: ASEP SOPIYAN | E39: 45896 | G39: PMD2508010 | H39: 3790592777 | I39: Pak Billy
A40: Bandung | B40: Pipamas | C40: PISLP02 | D40: Hari Wiharyana | E40: 45904 | G40: PMD2509003 | H40: 2800939910
A41: Bandung | B41: Pipamas | C41: PISLP03 | D41: Vacant | E41: 0 | G41: 0 | H41: 0
A42: Bandung | B42: Pipamas | C42: PISLP04 | D42: Gugun Hanafi | E42: 45727 | G42: PMD2503004 | H42: 1560108695
A43: Bandung | B43: Pipamas | C43: PISLP05 | D43: Vacant | E43: 0 | G43: 0 | H43: 0
A44: Bandung | B44: Pipamas | C44: PISLP06 | D44: Aditiya Muhammad Ramdhan | E44: 45727 | G44: PMD2503003 | H44: 7750965185
A45: Bandung | B45: Pipamas | C45: PISLP07 | D45: Bagus Gumilar | E45: 44858 | G45: PMD2210008 | H45: 0083879235
A46: Bandung | B46: Pipamas | C46: PISLP08 | D46: Muhammad Riki Safari | E46: 45792 | G46: PMD2109007 | H46: 2831290783
A47: Bandung | B47: Pipamas | C47: PISLP09 | D47: IKHSAN MAULANA YUSUF | E47: 45887 | G47: PMD2508004 | H47: 8320689768
...

Sheet Bogor
A1: ELEKTRIK
A3: Branch | B3: Divisi | C3: Kode Sales | D3: Januari | E3: Masuk | F3: Keluar | G3: NIK | H3: No Rek
A4: Bogor | B4: Elektrik | C4: ELSLE85 | D4: Syahri Rizki | E4: 45414 | G4: PMB2405003 | H4: 3720066482
A5: Bogor | B5: Elektrik | C5: ELSLE86 | D5: Wahyu Widiana | E5: 44903 | G5: PMB2212002 | H5: 7402130230
A6: Bogor | B6: Elektrik | C6: ELSLE87 | D6: Ryan Novi Handoko | E6: 44531 | G6: PMB2112002 | H6: 5015250876
A7: Bogor | B7: Elektrik | C7: ELSLE88 | D7: Muhamad Hasan | E7: 44091 | G7: PMB2009005 | H7: 5735335861
A9: ICI
A11: Branch | B11: Divisi | C11: Kode Sales | D11: Januari | E11: Masuk | F11: Keluar | G11: NIK | H11: No Rek
A12: Bogor | B12: ICI | C12: ICSLM80 | D12: Ramli Nasution | E12: 45817 | G12: PMB2506001 | H12: 7380496873
A13: Bogor | B13: ICI | C13: ICSLM81 | D13: Asep Permana Noor | E13: 45426 | G13: PMB2405006 | H13: 0953412346
A14: Bogor | B14: ICI | C14: ICSLM82 | D14: Fajar Nugraha | E14: 45616 | G14: PMB2411002 | H14: 1672882235
A15: Bogor | B15: ICI | C15: ICSLM83 | D15: Zaenudin | E15: 44341 | G15: PMB2105004 | H15: 8720710197
A16: Bogor | B16: ICI | C16: ICSLM84 | D16: Lucky Ghrstyan Syah | E16: 43731 | G16: PMB1909012 | H16: 3370017751
A17: Bogor | B17: ICI | C17: ICSLM85 | D17: Andri Prayitno | E17: 45530 | F17: 46027 | G17: PMB2408001 | H17: 8720384575
A19: PP
A21: Branch | B21: Divisi | C21: Kode Sales | D21: Januari | E21: Masuk | F21: Keluar | G21: NIK | H21: No Rek
A22: Bogor | B22: Pipa Pompa | C22: PPSLM85 | D22: Abdul Agus | E22: 45894 | G22: PMD2508009 | H22: 8720170974
A23: Bogor | B23: Pipa Pompa | C23: PPSLM86 | D23: Antonio Rifaldo | E23: 45607 | G23: PMB2411001 | H23: 0954790581
A24: Bogor | B24: Pipa Pompa | C24: PPSLM87 | D24: Ahmad Daud Abdullah | E24: 44979 | G24: PMB2302004 | H24: 7120059186
A25: Bogor | B25: Pipa Pompa | C25: PPSLM88 | D25: Rian Rudian | E25: 44739 | G25: PMB2207003 | H25: 1742087799
A26: Bogor | B26: Pipa Pompa | C26: PPSLM89 | D26: Gati Kusmanto | E26: 44902 | G26: PMB2212001 | H26: 0630100844
A28: PI
A30: Branch | B30: Divisi | C30: Kode Sales | D30: Januari | E30: Masuk | F30: Keluar | G30: NIK | H30: No Rek
A31: Bogor | B31: Pipamas | C31: PISLP81 | D31: Lili Murtado | E31: 44496 | G31: PMB2110006 | H31: 8691144780
A32: Bogor | B32: Pipamas | C32: PISLP82 | D32: Mulyadi | E32: kosong
A33: Bogor | B33: Pipamas | C33: PISLP83 | D33: Febiansyah | E33: 44903 | G33: PMB2212003 | H33: 5470418682
A34: Bogor | B34: Pipamas | C34: PISLP84 | D34: Artanto | E34: 45944 | G34: PMD2510002 | H34: 0953302303
A35: Bogor | B35: Pipamas | C35: PISLP85 | D35: Vacant | E35: 0 | G35: 0 | H35: 0

Sheet Cirebon
A1: ELEKTRIK
A3: Branch | B3: Divisi | C3: Kode Sales | D3: Januari | E3: Masuk | F3: Keluar | G3: NIK | H3: No Rek
A4: Cirebon | B4: Elektrik | C4: ELSLE60 | D4: Nurfadilah | E4: 44951 | G4: PMC2301001 | H4: 1342293292
A5: Cirebon | B5: Elektrik | C5: ELSLE61 | D5: Fanji Berliandy Azhari Ridzki | E5: 44536 | G5: PMC2112006 | H5: 8180224085
A6: Cirebon | B6: Elektrik | C6: ELSLE62 | D6: Ade Trihandoyo | E6: 45845 | G6: PMC2507002 | H6: 373802651
A7: Cirebon | B7: Elektrik | C7: ELSLE63 | D7: Fidyah Faroid | E7: 45502 | G7: PMC2407004 | H7: 8180505475
A8: Cirebon | B8: Elektrik | C8: ELSLE64 | D8: Eko Yoga Prawira | E8: 45708 | G8: PMC2502002 | H8: 1342833637
A9: Cirebon | B9: Elektrik | C9: ELSLE65 | D9: Ipan Wiguna | E9: 45643 | G9: PMC2412003 | H9: 2991983084
A11: PP
A13: Branch | B13: Divisi | C13: Kode Sales | D13: Januari | E13: Masuk | F13: Keluar | G13: NIK | H13: No Rek
A14: Cirebon | B14: Pipa Pompa | C14: PPSLM60 | D14: Deni Junaeni Adriyadi | E14: 45509 | G14: PMC2408001 | H14: 1342870354
A15: Cirebon | B15: Pipa Pompa | C15: PPSLM61 | D15: Imam Santoso | E15: 45079 | G15: PMC2306001 | H15: 1341798898
A16: Cirebon | B16: Pipa Pompa | C16: PPSLM62 | D16: Rahman Adi Kusuma | E16: 45502 | G16: PMC2407003 | H16: 1341470272
A17: Cirebon | B17: Pipa Pompa | C17: PPSLM63 | D17: Rohmanudin | E17: 45419 | G17: PMC2405002 | H17: 3741569866
A18: Cirebon | B18: Pipa Pompa | C18: PPSLM64 | D18: Willyanto | E18: 44655 | G18: PMC2204004 | H18: 8180355414
A19: Cirebon | B19: Pipa Pompa | C19: PPSLM65 | D19: Abdurokhim | E19: 45418 | G19: PMC2405001 | H19: 3741559241
A21: PI
A23: Branch | B23: Divisi | C23: Kode Sales | D23: Januari | E23: Masuk | F23: Keluar | G23: NIK | H23: No Rek
A24: Cirebon | B24: Pipamas | C24: PISLP60 | D24: Budi Handoko | E24: 45841 | G24: PMC2507001 | H24: 8180252151
A25: Cirebon | B25: Pipamas | C25: PISLP61 | D25: Hernado | E25: 45824 | G25: PMC2506002 | H25: 1342304294
A26: Cirebon | B26: Pipamas | C26: PISLP62 | D26: Mochamad Triana | E26: 45873 | G26: PMC 2508001 | H26: 8180322745

Sheet PCK
A1: ELEKTRIK
A3: Branch | B3: Divisi | C3: Kode Sales | D3: Januari | E3: Masuk | F3: Keluar | G3: NIK | H3: No Rek
A4: PCK | B4: Elektrik | C4: ELSLE25 | D4: Kiki Hadisurya | E4: 45649 | G4: PMK2412001 | H4: 0087042531 | I4: Pak Martin
A6: ICI
A8: Branch | B8: Divisi | C8: Kode Sales | D8: Januari | E8: Masuk | F8: Keluar | G8: NIK | H8: No Rek
A9: PCK | B9: ICI | C9: ICSLM21 | D9: Ujang Sulaeman | E9: 44137 | G9: PMK2011003 | H9: 3780397925
A10: PCK | B10: ICI | C10: ICSLM22 | D10: Ahmad Sanusi | E10: 45894 | G10: PMD2508008 | H10: 5745718288 | I10: Pak Adhi
A11: PCK | B11: ICI | C11: ICSLM23 | D11: Bonar Jumada | E11: 43349 | G11: PMK1809003 | H11: 5770551341
A12: PCK | B12: ICI | C12: ICSLM28 | D12: Adhi Gustiana | E12: 43332 | G12: PMK1808008 | H12: 2310272283
A14: PP
A16: Branch | B16: Divisi | C16: Kode Sales | D16: Januari | E16: Masuk | F16: Keluar | G16: NIK | H16: No Rek
A17: PCK | B17: Pipa Pompa | C17: PPSLM24 | D17: Asep Anang Rusmana | E17: 44538 | G17: PMK2112008 | H17: 1092167482 | I17: Pak Martin
A19: PI
A21: Branch | B21: Divisi | C21: Kode Sales | D21: Januari | E21: Masuk | F21: Keluar | G21: NIK | H21: No Rek
A22: PCK | B22: Pipamas | C22: PISLP26 | D22: Afif Mustafa | E22: 45104 | G22: PMK2306002 | H22: 0662788285

Sheet Tasik
A1: ELEKTRIK
A3: Branch | B3: Divisi | C3: Kode Sales | D3: Januari | E3: Masuk | F3: Keluar | G3: NIK | H3: No Rek
A4: Tasik | B4: Elektrik | C4: ELSLE71 | D4: Firmansyah | E4: 45468 | G4: PMT2406003 | H4: 3211177428
A5: Tasik | B5: Elektrik | C5: ELSLE72 | D5: Dhia Ul Iman | E5: 44734 | G5: PMT2206001 | H5: 3210914411 | I5: Pak Rikza
A6: Tasik | B6: Elektrik | C6: ELSLE73 | D6: Veby Rizky Fauzi | E6: 45558 | G6: PMT2409001 | H6: 0541384501
A7: Tasik | B7: Elektrik | C7: ELSLE74 | D7: Dian Haerandi | E7: 45820 | G7: PMT2506001 | H7: 3211265807
A8: Tasik | B8: Elektrik | C8: ELSLE75 | D8: Jejen Alkohiri | E8: 45679 | G8: PMT2501001 | H8: 3210680810
A10: ICI
A12: Branch | B12: Divisi | C12: Kode Sales | D12: Januari | E12: Masuk | F12: Keluar | G12: NIK | H12: No Rek
A13: Tasik | B13: ICI | C13: ICSLM71 | D13: Faizal Abdul Jabbar | E13: 44533 | G13: PMT2112005 | H13: 3210847285
A14: Tasik | B14: ICI | C14: ICSLM72 | D14: Septian Hermansyah | E14: 44781 | G14: PMT2208001 | H14: 3210939872
A15: Tasik | B15: ICI | C15: ICSLM73 | D15: Nandang Tata Yusmana | E15: 45824 | G15: PMT2506002 | H15: 0541621678
A17: PP
A19: Branch | B19: Divisi | C19: Kode Sales | D19: Januari | E19: Masuk | F19: Keluar | G19: NIK | H19: No Rek
A20: Tasik | B20: Pipa Pompa | C20: PPSLM71 | D20: EDI ROSYADI | E20: 24/12/2025
A21: Tasik | B21: Pipa Pompa | C21: PPSLM72 | D21: ADITYA APTA TRIPURNA | E21: 44907 | G21: PMT2212001 | H21: 0542022157
A22: Tasik | B22: Pipa Pompa | C22: PPSLM73 | D22: ANGGA DWITAMA | E22: 45936 | G22: PMD2510001 | H22: 1381618345
A23: Tasik | B23: Pipa Pompa | C23: PPSLM74 | D23: Asep Rachmat Sapaat | E23: 45824 | G23: PMT2506003 | H23: 0542132653
A24: Tasik | B24: Pipa Pompa | C24: PPSLM75 | D24: IRFAN SETIAWAN | E24: 45996 | G24: PMD2512002 | H24: 1381641738
A26: PI
A28: Branch | B28: Divisi | C28: Kode Sales | D28: Januari | E28: Masuk | F28: Keluar | G28: NIK | H28: No Rek
A29: Tasik | B29: Pipamas | C29: PISLP71 | D29: Dudi Sidik Permana | E29: 44835 | G29: PMT2209002 | H29: 2030529947
A30: Tasik | B30: Pipamas | C30: PISLP72 | D30: Rudi Ruswandi | E30: 44106 | G30: PMT2010001 | H30: 0541428037
A31: Tasik | B31: Pipamas | C31: PISLP73 | D31: Eri Aprrilian Rusliana | E31: 45803 | G31: PMT2505001 | H31: 2080770807
A32: Tasik | B32: Pipamas | C32: PISLP74 | D32: Dian Nursamsi | E32: 44771 | F32: 46038 | G32: PMT2207002 | H32: 2090798238
A33: Tasik | B33: Pipamas | C33: PISLP75 | D33: Vacant | E33: 0 | G33: 0 | H33: 0
